Workbook
Name ARA_Threshold: #REF!
Name ARP_Threshold: #REF!
Name DiffAmtHeader: #REF!
Name DiffPercentHeader: #REF!
Name MP: #REF!
Name Population: #REF!
Name S_Adjust_Data: #REF!
Name S_Adjust_GT: #REF!
Name S_AJE_Tot_Data: #REF!
Name S_AJE_Tot_GT: #REF!
Name S_CY_Beg_Data: #REF!
Name S_CY_Beg_GT: #REF!
Name S_CY_End_Data: #REF!
Name S_CY_End_GT: #REF!
Name S_Headings: #REF!
Name S_KeyValue: #REF!
Name S_PY_End_Data: #REF!
Name S_PY_End_GT: #REF!
Name S_RJE_Tot_Data: #REF!
Name S_RJE_Tot_GT: #REF!
Name TextRefCopy1: #REF!
Name TextRefCopy10: #REF!
Name TextRefCopy11: #REF!
Name TextRefCopy12: #REF!
Name TextRefCopy13: #REF!
Name TextRefCopy14: #REF!
Name TextRefCopy15: #REF!
Name TextRefCopy16: #REF!
Name TextRefCopy17: #REF!
Name TextRefCopy19: #REF!
Name TextRefCopy20: #REF!
Name TextRefCopy21: #REF!
Name TextRefCopy22: #REF!
Name TextRefCopy23: #REF!
Name TextRefCopy25: #REF!
Name TextRefCopy26: #REF!
Name TextRefCopy27: #REF!
Name TextRefCopy28: #REF!
Name TextRefCopy29: #REF!
Name TextRefCopy30: #REF!
Name TextRefCopy31: #REF!
Name TextRefCopy32: #REF!
Name TextRefCopy33: #REF!
Name TextRefCopy34: #REF!
Name TextRefCopy35: #REF!
Name TextRefCopy36: #REF!
Name TextRefCopy37: #REF!
Name TextRefCopy38: #REF!
Name TextRefCopy39: #REF!
Name TextRefCopy40: #REF!
Name TextRefCopy41: #REF!
Name TextRefCopy42: #REF!
Name TextRefCopy43: #REF!
Name TextRefCopy44: #REF!
Name TextRefCopy45: #REF!
Name TextRefCopy46: #REF!
Name TextRefCopy47: #REF!
Name TextRefCopy48: #REF!
Name TextRefCopy49: #REF!
Name TextRefCopy5: #REF!

Sheet YearlyAlif
A3: GLAcctDisp | B3: GLAcctDesc | C3: Y2014 | D3: Y2015 | E3: Y2016 | F3: Y2017 | G3: Y2018 | H3: Y2019 | I3: Y2020 | J3: Y2021 | K3: Y2022 | L3: Y2023 | M3: Y2024 | N3: Y2025 | O3: Acnt Group | P3: Expense Group
A4: 110001 | B4: LAND | C4: =SUMIF(ALIF_Y2014!$A:$A,$A4,ALIF_Y2014!$F:$F) -> 0 | D4: =SUMIF(ALIF_Y2015!$A:$A,$A4,ALIF_Y2015!$F:$F) -> 0 | E4: =SUMIF(ALIF_Y2016!$A:$A,$A4,ALIF_Y2016!$F:$F) -> 0 | F4: =SUMIF(ALIF_Y2017!$A:$A,$A4,ALIF_Y2017!$F:$F) -> 0 | G4: =SUMIF(ALIF_Y2018!$A:$A,$A4,ALIF_Y2018!$F:$F) -> 0 | H4: =SUMIF(ALIF_Y2019!$A:$A,$A4,ALIF_Y2019!$F:$F) -> 0 | I4: =SUMIF(ALIF_Y2020!$A:$A,$A4,ALIF_Y2020!$F:$F) -> 0 | J4: =SUMIF(ALIF_Y2021!$A:$A,$A4,ALIF_Y2021!$F:$F) -> 0 | K4: =SUMIF(ALIF_Y2022!$A:$A,$A4,ALIF_Y2022!$F:$F) -> 0 | L4: =SUMIF(ALIF_Y2023!$A:$A,$A4,ALIF_Y2023!$F:$F) -> 0 | M4: =SUMIF(ALIF_Y2024!$A:$A,$A4,ALIF_Y2024!$F:$F) -> 0 | N4: =SUMIF(ALIF_Y2025!$A:$A,$A4,ALIF_Y2025!$F:$F) -> 0 | O4: =_xlfn.XLOOKUP(A4,Map!A:A,Map!E:E) -> Property, plant and equipment | P4: =_xlfn.XLOOKUP(A4,Map!A:A,Map!D:D) -> Non-Current Assets
A5: 110002 | B5: BUILDINGS | C5: =SUMIF(ALIF_Y2014!$A:$A,$A5,ALIF_Y2014!$F:$F) -> 249682 | D5: =SUMIF(ALIF_Y2015!$A:$A,$A5,ALIF_Y2015!$F:$F) -> 249682 | E5: =SUMIF(ALIF_Y2016!$A:$A,$A5,ALIF_Y2016!$F:$F) -> 249682 | F5: =SUMIF(ALIF_Y2017!$A:$A,$A5,ALIF_Y2017!$F:$F) -> 249682 | G5: =SUMIF(ALIF_Y2018!$A:$A,$A5,ALIF_Y2018!$F:$F) -> 1.06505e+08 | H5: =SUMIF(ALIF_Y2019!$A:$A,$A5,ALIF_Y2019!$F:$F) -> 1.06505e+08 | I5: =SUMIF(ALIF_Y2020!$A:$A,$A5,ALIF_Y2020!$F:$F) -> 1.06505e+08 | J5: =SUMIF(ALIF_Y2021!$A:$A,$A5,ALIF_Y2021!$F:$F) -> 1.06505e+08 | K5: =SUMIF(ALIF_Y2022!$A:$A,$A5,ALIF_Y2022!$F:$F) -> 1.06505e+08 | L5: =SUMIF(ALIF_Y2023!$A:$A,$A5,ALIF_Y2023!$F:$F) -> 1.06505e+08 | M5: =SUMIF(ALIF_Y2024!$A:$A,$A5,ALIF_Y2024!$F:$F) -> 1.072962e+08 | N5: =SUMIF(ALIF_Y2025!$A:$A,$A5,ALIF_Y2025!$F:$F) -> 1.072962e+08 | O5: =_xlfn.XLOOKUP(A5,Map!A:A,Map!E:E) -> Property, plant and equipment | P5: =_xlfn.XLOOKUP(A5,Map!A:A,Map!D:D) -> Non-Current Assets
A6: 110003 | B6: DECORS AND INSTALLATIONS | C6: =SUMIF(ALIF_Y2014!$A:$A,$A6,ALIF_Y2014!$F:$F) -> 1765393.8 | D6: =SUMIF(ALIF_Y2015!$A:$A,$A6,ALIF_Y2015!$F:$F) -> 1773233.8 | E6: =SUMIF(ALIF_Y2016!$A:$A,$A6,ALIF_Y2016!$F:$F) -> 1773233.8 | F6: =SUMIF(ALIF_Y2017!$A:$A,$A6,ALIF_Y2017!$F:$F) -> 1773233.8 | G6: =SUMIF(ALIF_Y2018!$A:$A,$A6,ALIF_Y2018!$F:$F) -> 1824603.8 | H6: =SUMIF(ALIF_Y2019!$A:$A,$A6,ALIF_Y2019!$F:$F) -> 1920201.8 | I6: =SUMIF(ALIF_Y2020!$A:$A,$A6,ALIF_Y2020!$F:$F) -> 1765393.8 | J6: =SUMIF(ALIF_Y2021!$A:$A,$A6,ALIF_Y2021!$F:$F) -> 1765393.8 | K6: =SUMIF(ALIF_Y2022!$A:$A,$A6,ALIF_Y2022!$F:$F) -> 1765393.8 | L6: =SUMIF(ALIF_Y2023!$A:$A,$A6,ALIF_Y2023!$F:$F) -> 1765393.8 | M6: =SUMIF(ALIF_Y2024!$A:$A,$A6,ALIF_Y2024!$F:$F) -> 1765393.8 | N6: =SUMIF(ALIF_Y2025!$A:$A,$A6,ALIF_Y2025!$F:$F) -> 2296738 | O6: =_xlfn.XLOOKUP(A6,Map!A:A,Map!E:E) -> Property, plant and equipment | P6: =_xlfn.XLOOKUP(A6,Map!A:A,Map!D:D) -> Non-Current Assets
A7: 110004 | B7: MACHINERY AND EQUIPMENTS | C7: =SUMIF(ALIF_Y2014!$A:$A,$A7,ALIF_Y2014!$F:$F) -> 38561941 | D7: =SUMIF(ALIF_Y2015!$A:$A,$A7,ALIF_Y2015!$F:$F) -> 39518811 | E7: =SUMIF(ALIF_Y2016!$A:$A,$A7,ALIF_Y2016!$F:$F) -> 39914308 | F7: =SUMIF(ALIF_Y2017!$A:$A,$A7,ALIF_Y2017!$F:$F) -> 43898751 | G7: =SUMIF(ALIF_Y2018!$A:$A,$A7,ALIF_Y2018!$F:$F) -> 62879993 | H7: =SUMIF(ALIF_Y2019!$A:$A,$A7,ALIF_Y2019!$F:$F) -> 66375893 | I7: =SUMIF(ALIF_Y2020!$A:$A,$A7,ALIF_Y2020!$F:$F) -> 71133086 | J7: =SUMIF(ALIF_Y2021!$A:$A,$A7,ALIF_Y2021!$F:$F) -> 72216302 | K7: =SUMIF(ALIF_Y2022!$A:$A,$A7,ALIF_Y2022!$F:$F) -> 80282872 | L7: =SUMIF(ALIF_Y2023!$A:$A,$A7,ALIF_Y2023!$F:$F) -> 72478281 | M7: =SUMIF(ALIF_Y2024!$A:$A,$A7,ALIF_Y2024!$F:$F) -> 81812316 | N7: =SUMIF(ALIF_Y2025!$A:$A,$A7,ALIF_Y2025!$F:$F) -> 93774591 | O7: =_xlfn.XLOOKUP(A7,Map!A:A,Map!E:E) -> Property, plant and equipment | P7: =_xlfn.XLOOKUP(A7,Map!A:A,Map!D:D) -> Non-Current Assets
A8: 110006 | B8: VEHICLES | C8: =SUMIF(ALIF_Y2014!$A:$A,$A8,ALIF_Y2014!$F:$F) -> 1446052.1 | D8: =SUMIF(ALIF_Y2015!$A:$A,$A8,ALIF_Y2015!$F:$F) -> 1446052.1 | E8: =SUMIF(ALIF_Y2016!$A:$A,$A8,ALIF_Y2016!$F:$F) -> 1548852.1 | F8: =SUMIF(ALIF_Y2017!$A:$A,$A8,ALIF_Y2017!$F:$F) -> 1891752.1 | G8: =SUMIF(ALIF_Y2018!$A:$A,$A8,ALIF_Y2018!$F:$F) -> 2495208.5 | H8: =SUMIF(ALIF_Y2019!$A:$A,$A8,ALIF_Y2019!$F:$F) -> 2791352.1 | I8: =SUMIF(ALIF_Y2020!$A:$A,$A8,ALIF_Y2020!$F:$F) -> 2602761 | J8: =SUMIF(ALIF_Y2021!$A:$A,$A8,ALIF_Y2021!$F:$F) -> 2675451 | K8: =SUMIF(ALIF_Y2022!$A:$A,$A8,ALIF_Y2022!$F:$F) -> 3033459.7 | L8: =SUMIF(ALIF_Y2023!$A:$A,$A8,ALIF_Y2023!$F:$F) -> 3090755.7 | M8: =SUMIF(ALIF_Y2024!$A:$A,$A8,ALIF_Y2024!$F:$F) -> 3327255.7 | N8: =SUMIF(ALIF_Y2025!$A:$A,$A8,ALIF_Y2025!$F:$F) -> 3650255.2 | O8: =_xlfn.XLOOKUP(A8,Map!A:A,Map!E:E) -> Property, plant and equipment | P8: =_xlfn.XLOOKUP(A8,Map!A:A,Map!D:D) -> Non-Current Assets
A9: 110007 | B9: OFFICE EQUIPMENTS& COMPUTR PROGRAMS INSTALLATIONS | C9: =SUMIF(ALIF_Y2014!$A:$A,$A9,ALIF_Y2014!$F:$F) -> 798523.45 | D9: =SUMIF(ALIF_Y2015!$A:$A,$A9,ALIF_Y2015!$F:$F) -> 798523.45 | E9: =SUMIF(ALIF_Y2016!$A:$A,$A9,ALIF_Y2016!$F:$F) -> 798523.45 | F9: =SUMIF(ALIF_Y2017!$A:$A,$A9,ALIF_Y2017!$F:$F) -> 798523.45 | G9: =SUMIF(ALIF_Y2018!$A:$A,$A9,ALIF_Y2018!$F:$F) -> 876515.95 | H9: =SUMIF(ALIF_Y2019!$A:$A,$A9,ALIF_Y2019!$F:$F) -> 876515.95 | I9: =SUMIF(ALIF_Y2020!$A:$A,$A9,ALIF_Y2020!$F:$F) -> 1191638.9 | J9: =SUMIF(ALIF_Y2021!$A:$A,$A9,ALIF_Y2021!$F:$F) -> 2056841.1 | K9: =SUMIF(ALIF_Y2022!$A:$A,$A9,ALIF_Y2022!$F:$F) -> 2100287.9 | L9: =SUMIF(ALIF_Y2023!$A:$A,$A9,ALIF_Y2023!$F:$F) -> 2100287.9 | M9: =SUMIF(ALIF_Y2024!$A:$A,$A9,ALIF_Y2024!$F:$F) -> 2269918.4 | N9: =SUMIF(ALIF_Y2025!$A:$A,$A9,ALIF_Y2025!$F:$F) -> 2677196.3 | O9: =_xlfn.XLOOKUP(A9,Map!A:A,Map!E:E) -> Property, plant and equipment | P9: =_xlfn.XLOOKUP(A9,Map!A:A,Map!D:D) -> Non-Current Assets
A10: 110008 | B10: FURNITURE AND FITTINGS | C10: =SUMIF(ALIF_Y2014!$A:$A,$A10,ALIF_Y2014!$F:$F) -> 191765.4 | D10: =SUMIF(ALIF_Y2015!$A:$A,$A10,ALIF_Y2015!$F:$F) -> 191765.4 | E10: =SUMIF(ALIF_Y2016!$A:$A,$A10,ALIF_Y2016!$F:$F) -> 191765.4 | F10: =SUMIF(ALIF_Y2017!$A:$A,$A10,ALIF_Y2017!$F:$F) -> 191765.4 | G10: =SUMIF(ALIF_Y2018!$A:$A,$A10,ALIF_Y2018!$F:$F) -> 533547.4 | H10: =SUMIF(ALIF_Y2019!$A:$A,$A10,ALIF_Y2019!$F:$F) -> 616788.35 | I10: =SUMIF(ALIF_Y2020!$A:$A,$A10,ALIF_Y2020!$F:$F) -> 961301.68 | J10: =SUMIF(ALIF_Y2021!$A:$A,$A10,ALIF_Y2021!$F:$F) -> 1015678.5 | K10: =SUMIF(ALIF_Y2022!$A:$A,$A10,ALIF_Y2022!$F:$F) -> 1101801 | L10: =SUMIF(ALIF_Y2023!$A:$A,$A10,ALIF_Y2023!$F:$F) -> 1101801 | M10: =SUMIF(ALIF_Y2024!$A:$A,$A10,ALIF_Y2024!$F:$F) -> 1134240.1 | N10: =SUMIF(ALIF_Y2025!$A:$A,$A10,ALIF_Y2025!$F:$F) -> 1155192.2 | O10: =_xlfn.XLOOKUP(A10,Map!A:A,Map!E:E) -> Property, plant and equipment | P10: =_xlfn.XLOOKUP(A10,Map!A:A,Map!D:D) -> Non-Current Assets
A11: 111009 | B11: RIGHT OF USE ASSETS | C11: =SUMIF(ALIF_Y2014!$A:$A,$A11,ALIF_Y2014!$F:$F) -> 0 | D11: =SUMIF(ALIF_Y2015!$A:$A,$A11,ALIF_Y2015!$F:$F) -> 0 | E11: =SUMIF(ALIF_Y2016!$A:$A,$A11,ALIF_Y2016!$F:$F) -> 0 | F11: =SUMIF(ALIF_Y2017!$A:$A,$A11,ALIF_Y2017!$F:$F) -> 0 | G11: =SUMIF(ALIF_Y2018!$A:$A,$A11,ALIF_Y2018!$F:$F) -> 0 | H11: =SUMIF(ALIF_Y2019!$A:$A,$A11,ALIF_Y2019!$F:$F) -> 2020135 | I11: =SUMIF(ALIF_Y2020!$A:$A,$A11,ALIF_Y2020!$F:$F) -> 2020135 | J11: =SUMIF(ALIF_Y2021!$A:$A,$A11,ALIF_Y2021!$F:$F) -> 2020135 | K11: =SUMIF(ALIF_Y2022!$A:$A,$A11,ALIF_Y2022!$F:$F) -> 2020135 | L11: =SUMIF(ALIF_Y2023!$A:$A,$A11,ALIF_Y2023!$F:$F) -> 2020135 | M11: =SUMIF(ALIF_Y2024!$A:$A,$A11,ALIF_Y2024!$F:$F) -> 2020135 | N11: =SUMIF(ALIF_Y2025!$A:$A,$A11,ALIF_Y2025!$F:$F) -> 3674470.8 | O11: =_xlfn.XLOOKUP(A11,Map!A:A,Map!E:E) -> Right of use | P11: =_xlfn.XLOOKUP(A11,Map!A:A,Map!D:D) -> Non-Current Assets
A12: 111010 | B12: INSTALLATION IN PROGRESS | C12: =SUMIF(ALIF_Y2014!$A:$A,$A12,ALIF_Y2014!$F:$F) -> 0 | D12: =SUMIF(ALIF_Y2015!$A:$A,$A12,ALIF_Y2015!$F:$F) -> 0 | E12: =SUMIF(ALIF_Y2016!$A:$A,$A12,ALIF_Y2016!$F:$F) -> 0 | F12: =SUMIF(ALIF_Y2017!$A:$A,$A12,ALIF_Y2017!$F:$F) -> 0 | G12: =SUMIF(ALIF_Y2018!$A:$A,$A12,ALIF_Y2018!$F:$F) -> 0 | H12: =SUMIF(ALIF_Y2019!$A:$A,$A12,ALIF_Y2019!$F:$F) -> 0 | I12: =SUMIF(ALIF_Y2020!$A:$A,$A12,ALIF_Y2020!$F:$F) -> 0 | J12: =SUMIF(ALIF_Y2021!$A:$A,$A12,ALIF_Y2021!$F:$F) -> 0 | K12: =SUMIF(ALIF_Y2022!$A:$A,$A12,ALIF_Y2022!$F:$F) -> 0 | L12: =SUMIF(ALIF_Y2023!$A:$A,$A12,ALIF_Y2023!$F:$F) -> 0 | M12: =SUMIF(ALIF_Y2024!$A:$A,$A12,ALIF_Y2024!$F:$F) -> 0 | N12: =SUMIF(ALIF_Y2025!$A:$A,$A12,ALIF_Y2025!$F:$F) -> 17130501 | O12: =_xlfn.XLOOKUP(A12,Map!A:A,Map!E:E) -> Property, plant and equipment | P12: =_xlfn.XLOOKUP(A12,Map!A:A,Map!D:D) -> Non-Current Assets
A13: 111013 | B13: INSTALLATION IN PROGRESS JEDDAH PROJECT | C13: =SUMIF(ALIF_Y2014!$A:$A,$A13,ALIF_Y2014!$F:$F) -> 0 | D13: =SUMIF(ALIF_Y2015!$A:$A,$A13,ALIF_Y2015!$F:$F) -> 10769235 | E13: =SUMIF(ALIF_Y2016!$A:$A,$A13,ALIF_Y2016!$F:$F) -> 99946347 | F13: =SUMIF(ALIF_Y2017!$A:$A,$A13,ALIF_Y2017!$F:$F) -> 1.022654e+08 | G13: =SUMIF(ALIF_Y2018!$A:$A,$A13,ALIF_Y2018!$F:$F) -> 5140199 | H13: =SUMIF(ALIF_Y2019!$A:$A,$A13,ALIF_Y2019!$F:$F) -> 8976734.2 | I13: =SUMIF(ALIF_Y2020!$A:$A,$A13,ALIF_Y2020!$F:$F) -> 0 | J13: =SUMIF(ALIF_Y2021!$A:$A,$A13,ALIF_Y2021!$F:$F) -> 0 | K13: =SUMIF(ALIF_Y2022!$A:$A,$A13,ALIF_Y2022!$F:$F) -> 0 | L13: =SUMIF(ALIF_Y2023!$A:$A,$A13,ALIF_Y2023!$F:$F) -> 569470.02 | M13: =SUMIF(ALIF_Y2024!$A:$A,$A13,ALIF_Y2024!$F:$F) -> 3661922.8 | N13: =SUMIF(ALIF_Y2025!$A:$A,$A13,ALIF_Y2025!$F:$F) -> -543176.42 | O13: =_xlfn.XLOOKUP(A13,Map!A:A,Map!E:E) -> Property, plant and equipment | P13: =_xlfn.XLOOKUP(A13,Map!A:A,Map!D:D) -> Non-Current Assets
A14: 111099 | B14: Fixed Assets Clearing Accounts | C14: =SUMIF(ALIF_Y2014!$A:$A,$A14,ALIF_Y2014!$F:$F) -> 0 | D14: =SUMIF(ALIF_Y2015!$A:$A,$A14,ALIF_Y2015!$F:$F) -> 0 | E14: =SUMIF(ALIF_Y2016!$A:$A,$A14,ALIF_Y2016!$F:$F) -> 0 | F14: =SUMIF(ALIF_Y2017!$A:$A,$A14,ALIF_Y2017!$F:$F) -> 0 | G14: =SUMIF(ALIF_Y2018!$A:$A,$A14,ALIF_Y2018!$F:$F) -> 0 | H14: =SUMIF(ALIF_Y2019!$A:$A,$A14,ALIF_Y2019!$F:$F) -> 0 | I14: =SUMIF(ALIF_Y2020!$A:$A,$A14,ALIF_Y2020!$F:$F) -> 0 | J14: =SUMIF(ALIF_Y2021!$A:$A,$A14,ALIF_Y2021!$F:$F) -> 0 | K14: =SUMIF(ALIF_Y2022!$A:$A,$A14,ALIF_Y2022!$F:$F) -> 0 | L14: =SUMIF(ALIF_Y2023!$A:$A,$A14,ALIF_Y2023!$F:$F) -> 0 | M14: =SUMIF(ALIF_Y2024!$A:$A,$A14,ALIF_Y2024!$F:$F) -> 220102.93 | N14: =SUMIF(ALIF_Y2025!$A:$A,$A14,ALIF_Y2025!$F:$F) -> 135753.14 | O14: =_xlfn.XLOOKUP(A14,Map!A:A,Map!E:E) -> Property, plant and equipment | P14: =_xlfn.XLOOKUP(A14,Map!A:A,Map!D:D) -> Non-Current Assets
A15: 120001 | B15: ACCUM DEPR BUILDINGS | C15: =SUMIF(ALIF_Y2014!$A:$A,$A15,ALIF_Y2014!$F:$F) -> -227682.83 | D15: =SUMIF(ALIF_Y2015!$A:$A,$A15,ALIF_Y2015!$F:$F) -> -242695.31 | E15: =SUMIF(ALIF_Y2016!$A:$A,$A15,ALIF_Y2016!$F:$F) -> -249150.34 | F15: =SUMIF(ALIF_Y2017!$A:$A,$A15,ALIF_Y2017!$F:$F) -> -249682.01 | G15: =SUMIF(ALIF_Y2018!$A:$A,$A15,ALIF_Y2018!$F:$F) -> -694867.69 | H15: =SUMIF(ALIF_Y2019!$A:$A,$A15,ALIF_Y2019!$F:$F) -> -2186446.3 | I15: =SUMIF(ALIF_Y2020!$A:$A,$A15,ALIF_Y2020!$F:$F) -> -3753290.5 | J15: =SUMIF(ALIF_Y2021!$A:$A,$A15,ALIF_Y2021!$F:$F) -> -5320134.7 | K15: =SUMIF(ALIF_Y2022!$A:$A,$A15,ALIF_Y2022!$F:$F) -> -6886978.9 | L15: =SUMIF(ALIF_Y2023!$A:$A,$A15,ALIF_Y2023!$F:$F) -> -8453823.1 | M15: =SUMIF(ALIF_Y2024!$A:$A,$A15,ALIF_Y2024!$F:$F) -> -10037151 | N15: =SUMIF(ALIF_Y2025!$A:$A,$A15,ALIF_Y2025!$F:$F) -> -11630035 | O15: =_xlfn.XLOOKUP(A15,Map!A:A,Map!E:E) -> Property, plant and equipment | P15: =_xlfn.XLOOKUP(A15,Map!A:A,Map!D:D) -> Non-Current Assets
... A269: 800002 | B269: AIMS HOLDING EXP OF CURRENT ACC | C269: =SUMIF(ALIF_Y2014!$A:$A,$A269,ALIF_Y2014!$F:$F) -> 0 | D269: =SUMIF(ALIF_Y2015!$A:$A,$A269,ALIF_Y2015!$F:$F) -> 0 | E269: =SUMIF(ALIF_Y2016!$A:$A,$A269,ALIF_Y2016!$F:$F) -> 0 | F269: =SUMIF(ALIF_Y2017!$A:$A,$A269,ALIF_Y2017!$F:$F) -> 0 | G269: =SUMIF(ALIF_Y2018!$A:$A,$A269,ALIF_Y2018!$F:$F) -> 0 | H269: =SUMIF(ALIF_Y2019!$A:$A,$A269,ALIF_Y2019!$F:$F) -> 0 | I269: =SUMIF(ALIF_Y2020!$A:$A,$A269,ALIF_Y2020!$F:$F) -> 0 | J269: =SUMIF(ALIF_Y2021!$A:$A,$A269,ALIF_Y2021!$F:$F) -> 0 | K269: =SUMIF(ALIF_Y2022!$A:$A,$A269,ALIF_Y2022!$F:$F) -> 700886 | L269: =SUMIF(ALIF_Y2023!$A:$A,$A269,ALIF_Y2023!$F:$F) -> 0 | M269: =SUMIF(ALIF_Y2024!$A:$A,$A269,ALIF_Y2024!$F:$F) -> 0 | N269: =SUMIF(ALIF_Y2025!$A:$A,$A269,ALIF_Y2025!$F:$F) -> 0 | O269: =_xlfn.XLOOKUP(A269,Map!A:A,Map!E:E) -> AIMS expenses | P269: =_xlfn.XLOOKUP(A269,Map!A:A,Map!D:D) -> General and Admin
C271: =SUBTOTAL(9,C4:C270) -> 3603438.5 | D271: =SUBTOTAL(9,D4:D270) -> 1318911.2 | E271: =SUBTOTAL(9,E4:E270) -> 3619649 | F271: =SUBTOTAL(9,F4:F270) -> 3261022.8 | G271: =SUBTOTAL(9,G4:G270) -> 485044.33 | H271: =SUBTOTAL(9,H4:H270) -> 1089346.1 | I271: =SUBTOTAL(9,I4:I270) -> 1237901.3 | J271: =SUBTOTAL(9,J4:J270) -> 1339380.2 | ... N271: =SUBTOTAL(9,N4:N270) -> -1566334.4

Sheet BS
A1: AIMS INDUSTRIAL
A2: Balance Sheet
A3: 31 December 2025 | F3: 1 | L3: 2
D5: Y2014 | E5: Y2015 | F5: Y2016 | G5: Y2017 | H5: Y2018 | I5: Y2019 | J5: Y2020 | K5: Y2021 | L5: Y2022 | M5: Y2023 | N5: Y2024 | O5: Y2025
B6: Current assets
B7: Cash and cash equivalents | D7: =SUMIF(ALIF_Y2014!$I:$I,$B7,ALIF_Y2014!$F:$F) -> 11085979 | E7: =SUMIF(ALIF_Y2015!$I:$I,$B7,ALIF_Y2015!$F:$F) -> 4470130.8 | F7: =SUMIF(ALIF_Y2016!$I:$I,$B7,ALIF_Y2016!$F:$F) -> 4689654.8 | G7: =SUMIF(ALIF_Y2017!$I:$I,$B7,ALIF_Y2017!$F:$F) -> 7257276.1 | H7: =SUMIF(ALIF_Y2018!$I:$I,$B7,ALIF_Y2018!$F:$F) -> 8817544.4 | I7: =SUMIF(ALIF_Y2019!$I:$I,$B7,ALIF_Y2019!$F:$F) -> 6590030 | J7: =SUMIF(ALIF_Y2020!$I:$I,$B7,ALIF_Y2020!$F:$F) -> 40745293 | K7: =SUMIF(ALIF_Y2021!$I:$I,$B7,ALIF_Y2021!$F:$F) -> 10651132 | L7: =SUMIF(ALIF_Y2022!$I:$I,$B7,ALIF_Y2022!$F:$F) -> 13695029 | M7: =SUMIF(ALIF_Y2023!$I:$I,$B7,ALIF_Y2023!$F:$F) -> 4063524.4 | N7: =SUMIF(ALIF_Y2024!$I:$I,$B7,ALIF_Y2024!$F:$F) -> 1103703.9 | O7: =SUMIF(ALIF_Y2025!$I:$I,$B7,ALIF_Y2025!$F:$F) -> 1510705
B8: Trade receivables | D8: =SUMIF(ALIF_Y2014!$I:$I,$B8,ALIF_Y2014!$F:$F) -> 34778327 | E8: =SUMIF(ALIF_Y2015!$I:$I,$B8,ALIF_Y2015!$F:$F) -> 35513977 | F8: =SUMIF(ALIF_Y2016!$I:$I,$B8,ALIF_Y2016!$F:$F) -> 36110502 | G8: =SUMIF(ALIF_Y2017!$I:$I,$B8,ALIF_Y2017!$F:$F) -> 35801104 | H8: =SUMIF(ALIF_Y2018!$I:$I,$B8,ALIF_Y2018!$F:$F) -> 34900866 | I8: =SUMIF(ALIF_Y2019!$I:$I,$B8,ALIF_Y2019!$F:$F) -> 40286632 | J8: =SUMIF(ALIF_Y2020!$I:$I,$B8,ALIF_Y2020!$F:$F) -> 35451877 | K8: =SUMIF(ALIF_Y2021!$I:$I,$B8,ALIF_Y2021!$F:$F) -> 59814195 | L8: =SUMIF(ALIF_Y2022!$I:$I,$B8,ALIF_Y2022!$F:$F) -> 69444422 | M8: =SUMIF(ALIF_Y2023!$I:$I,$B8,ALIF_Y2023!$F:$F) -> 32974816 | N8: =SUMIF(ALIF_Y2024!$I:$I,$B8,ALIF_Y2024!$F:$F) -> 45208932 | O8: =SUMIF(ALIF_Y2025!$I:$I,$B8,ALIF_Y2025!$F:$F) -> 34614828
B9: Prepaid expenses | D9: =SUMIF(ALIF_Y2014!$I:$I,$B9,ALIF_Y2014!$F:$F) -> 8670708.6 | E9: =SUMIF(ALIF_Y2015!$I:$I,$B9,ALIF_Y2015!$F:$F) -> 7700042.4 | F9: =SUMIF(ALIF_Y2016!$I:$I,$B9,ALIF_Y2016!$F:$F) -> 6566761.5 | G9: =SUMIF(ALIF_Y2017!$I:$I,$B9,ALIF_Y2017!$F:$F) -> 13100548 | H9: =SUMIF(ALIF_Y2018!$I:$I,$B9,ALIF_Y2018!$F:$F) -> 10942639 | I9: =SUMIF(ALIF_Y2019!$I:$I,$B9,ALIF_Y2019!$F:$F) -> 8522666 | J9: =SUMIF(ALIF_Y2020!$I:$I,$B9,ALIF_Y2020!$F:$F) -> 3692329.5 | K9: =SUMIF(ALIF_Y2021!$I:$I,$B9,ALIF_Y2021!$F:$F) -> 5210137.9 | L9: =SUMIF(ALIF_Y2022!$I:$I,$B9,ALIF_Y2022!$F:$F) -> 1107166 | M9: =SUMIF(ALIF_Y2023!$I:$I,$B9,ALIF_Y2023!$F:$F) -> 4772239.2 | N9: =SUMIF(ALIF_Y2024!$I:$I,$B9,ALIF_Y2024!$F:$F) -> 14758204 | O9: =SUMIF(ALIF_Y2025!$I:$I,$B9,ALIF_Y2025!$F:$F) -> 10384903
B10: Inventories | D10: =SUMIF(ALIF_Y2014!$I:$I,$B10,ALIF_Y2014!$F:$F) -> 34065376 | E10: =SUMIF(ALIF_Y2015!$I:$I,$B10,ALIF_Y2015!$F:$F) -> 28412734 | F10: =SUMIF(ALIF_Y2016!$I:$I,$B10,ALIF_Y2016!$F:$F) -> 31557771 | G10: =SUMIF(ALIF_Y2017!$I:$I,$B10,ALIF_Y2017!$F:$F) -> 25847131 | H10: =SUMIF(ALIF_Y2018!$I:$I,$B10,ALIF_Y2018!$F:$F) -> 65632734 | I10: =SUMIF(ALIF_Y2019!$I:$I,$B10,ALIF_Y2019!$F:$F) -> 63336468 | J10: =SUMIF(ALIF_Y2020!$I:$I,$B10,ALIF_Y2020!$F:$F) -> 45810721 | K10: =SUMIF(ALIF_Y2021!$I:$I,$B10,ALIF_Y2021!$F:$F) -> 60639675 | L10: =SUMIF(ALIF_Y2022!$I:$I,$B10,ALIF_Y2022!$F:$F) -> 93415465 | M10: =SUMIF(ALIF_Y2023!$I:$I,$B10,ALIF_Y2023!$F:$F) -> 45411605 | N10: =SUMIF(ALIF_Y2024!$I:$I,$B10,ALIF_Y2024!$F:$F) -> 59932685 | O10: =SUMIF(ALIF_Y2025!$I:$I,$B10,ALIF_Y2025!$F:$F) -> 1.1802975e+08
B11: Total current assets | D11: =SUM(D7:D10) -> 88600391 | E11: =SUM(E7:E10) -> 76096885 | F11: =SUM(F7:F10) -> 78924689 | G11: =SUM(G7:G10) -> 82006058 | H11: =SUM(H7:H10) -> 1.2029378e+08 | I11: =SUM(I7:I10) -> 1.187358e+08 | J11: =SUM(J7:J10) -> 1.2570022e+08 | K11: =SUM(K7:K10) -> 1.3631514e+08 | ... O11: =SUM(O7:O10) -> 1.6454018e+08
B13: Non-current assets
B14: Due from RP | D14: =SUMIF(ALIF_Y2014!$I:$I,$B14,ALIF_Y2014!$F:$F) -> 0 | E14: =SUMIF(ALIF_Y2015!$I:$I,$B14,ALIF_Y2015!$F:$F) -> 0 | F14: =SUMIF(ALIF_Y2016!$I:$I,$B14,ALIF_Y2016!$F:$F) -> 0 | G14: =SUMIF(ALIF_Y2017!$I:$I,$B14,ALIF_Y2017!$F:$F) -> 0 | H14: =SUMIF(ALIF_Y2018!$I:$I,$B14,ALIF_Y2018!$F:$F) -> 0 | I14: =SUMIF(ALIF_Y2019!$I:$I,$B14,ALIF_Y2019!$F:$F) -> 0 | J14: =SUMIF(ALIF_Y2020!$I:$I,$B14,ALIF_Y2020!$F:$F) -> 0 | K14: =SUMIF(ALIF_Y2021!$I:$I,$B14,ALIF_Y2021!$F:$F) -> 0 | L14: =SUMIF(ALIF_Y2022!$I:$I,$B14,ALIF_Y2022!$F:$F) -> 0 | M14: =SUMIF(ALIF_Y2023!$I:$I,$B14,ALIF_Y2023!$F:$F) -> 0 | N14: =SUMIF(ALIF_Y2024!$I:$I,$B14,ALIF_Y2024!$F:$F) -> 0 | O14: =SUMIF(ALIF_Y2025!$I:$I,$B14,ALIF_Y2025!$F:$F) -> 0
B15: Property, plant and equipment | D15: =SUMIF(ALIF_Y2014!$I:$I,$B15,ALIF_Y2014!$F:$F) -> 19388806 | E15: =SUMIF(ALIF_Y2015!$I:$I,$B15,ALIF_Y2015!$F:$F) -> 27222646 | F15: =SUMIF(ALIF_Y2016!$I:$I,$B15,ALIF_Y2016!$F:$F) -> 1.1316719e+08 | G15: =SUMIF(ALIF_Y2017!$I:$I,$B15,ALIF_Y2017!$F:$F) -> 1.160029e+08 | H15: =SUMIF(ALIF_Y2018!$I:$I,$B15,ALIF_Y2018!$F:$F) -> 1.4038536e+08 | I15: =SUMIF(ALIF_Y2019!$I:$I,$B15,ALIF_Y2019!$F:$F) -> 1.4278867e+08 | J15: =SUMIF(ALIF_Y2020!$I:$I,$B15,ALIF_Y2020!$F:$F) -> 1.3888052e+08 | K15: =SUMIF(ALIF_Y2021!$I:$I,$B15,ALIF_Y2021!$F:$F) -> 1.3563953e+08 | L15: =SUMIF(ALIF_Y2022!$I:$I,$B15,ALIF_Y2022!$F:$F) -> 1.3826324e+08 | M15: =SUMIF(ALIF_Y2023!$I:$I,$B15,ALIF_Y2023!$F:$F) -> 1.3128693e+08 | N15: =SUMIF(ALIF_Y2024!$I:$I,$B15,ALIF_Y2024!$F:$F) -> 1.3864062e+08 | O15: =SUMIF(ALIF_Y2025!$I:$I,$B15,ALIF_Y2025!$F:$F) -> 1.5813975e+08
B16: Right of use | D16: =SUMIF(ALIF_Y2014!$I:$I,$B16,ALIF_Y2014!$F:$F) -> 0 | E16: =SUMIF(ALIF_Y2015!$I:$I,$B16,ALIF_Y2015!$F:$F) -> 0 | F16: =SUMIF(ALIF_Y2016!$I:$I,$B16,ALIF_Y2016!$F:$F) -> 0 | G16: =SUMIF(ALIF_Y2017!$I:$I,$B16,ALIF_Y2017!$F:$F) -> 0 | H16: =SUMIF(ALIF_Y2018!$I:$I,$B16,ALIF_Y2018!$F:$F) -> 0 | I16: =SUMIF(ALIF_Y2019!$I:$I,$B16,ALIF_Y2019!$F:$F) -> 1995348 | J16: =SUMIF(ALIF_Y2020!$I:$I,$B16,ALIF_Y2020!$F:$F) -> 1846625.5 | K16: =SUMIF(ALIF_Y2021!$I:$I,$B16,ALIF_Y2021!$F:$F) -> 1686512.5 | L16: =SUMIF(ALIF_Y2022!$I:$I,$B16,ALIF_Y2022!$F:$F) -> 1537181.1 | M16: =SUMIF(ALIF_Y2023!$I:$I,$B16,ALIF_Y2023!$F:$F) -> 1374274.1 | N16: =SUMIF(ALIF_Y2024!$I:$I,$B16,ALIF_Y2024!$F:$F) -> 1225552.5 | O16: =SUMIF(ALIF_Y2025!$I:$I,$B16,ALIF_Y2025!$F:$F) -> 2545644.4
B17: Total non-current assets | D17: =SUM(D14:D16) -> 19388806 | E17: =SUM(E14:E16) -> 27222646 | F17: =SUM(F14:F16) -> 1.1316719e+08 | G17: =SUM(G14:G16) -> 1.160029e+08 | H17: =SUM(H14:H16) -> 1.4038536e+08 | I17: =SUM(I14:I16) -> 1.4478402e+08 | J17: =SUM(J14:J16) -> 1.4072714e+08 | K17: =SUM(K14:K16) -> 1.3732605e+08 | ... O17: =SUM(O14:O16) -> 1.6068539e+08
B19: TOTAL ASSETS | D19: =D11+D17 -> 1.079892e+08 | E19: =E11+E17 -> 1.0331953e+08 | F19: =F11+F17 -> 1.9209188e+08 | G19: =G11+G17 -> 1.9800896e+08 | H19: =H11+H17 -> 2.6067914e+08 | I19: =I11+I17 -> 2.6351982e+08 | J19: =J11+J17 -> 2.6642736e+08 | K19: =K11+K17 -> 2.7364119e+08 | ... O19: =O11+O17 -> 3.2522557e+08
B21: LIABILITIES AND SHAREHOLDERS' EQUITY
B22: Current liabilities
B23: Short-term Murabaha loans | D23: =-SUMIF(ALIF_Y2014!$I:$I,$B23,ALIF_Y2014!$F:$F) -> 24897662 | E23: =-SUMIF(ALIF_Y2015!$I:$I,$B23,ALIF_Y2015!$F:$F) -> 11975999 | F23: =-SUMIF(ALIF_Y2016!$I:$I,$B23,ALIF_Y2016!$F:$F) -> 26152571 | G23: =-SUMIF(ALIF_Y2017!$I:$I,$B23,ALIF_Y2017!$F:$F) -> 0 | H23: =-SUMIF(ALIF_Y2018!$I:$I,$B23,ALIF_Y2018!$F:$F) -> 60835098 | I23: =-SUMIF(ALIF_Y2019!$I:$I,$B23,ALIF_Y2019!$F:$F) -> 67558357 | J23: =-SUMIF(ALIF_Y2020!$I:$I,$B23,ALIF_Y2020!$F:$F) -> 87069638 | K23: =-SUMIF(ALIF_Y2021!$I:$I,$B23,ALIF_Y2021!$F:$F) -> 93444858 | L23: =-SUMIF(ALIF_Y2022!$I:$I,$B23,ALIF_Y2022!$F:$F) -> 1.2918116e+08 | M23: =-SUMIF(ALIF_Y2023!$I:$I,$B23,ALIF_Y2023!$F:$F) -> 83699243 | N23: =-SUMIF(ALIF_Y2024!$I:$I,$B23,ALIF_Y2024!$F:$F) -> 1.1139247e+08 | O23: =-SUMIF(ALIF_Y2025!$I:$I,$B23,ALIF_Y2025!$F:$F) -> 1.9339682e+08
B24: Lease liability - current portion | D24: =-SUMIF(ALIF_Y2014!$I:$I,$B24,ALIF_Y2014!$F:$F) -> 0 | E24: =-SUMIF(ALIF_Y2015!$I:$I,$B24,ALIF_Y2015!$F:$F) -> 0 | F24: =-SUMIF(ALIF_Y2016!$I:$I,$B24,ALIF_Y2016!$F:$F) -> 0 | G24: =-SUMIF(ALIF_Y2017!$I:$I,$B24,ALIF_Y2017!$F:$F) -> 0 | H24: =-SUMIF(ALIF_Y2018!$I:$I,$B24,ALIF_Y2018!$F:$F) -> 0 | I24: =-SUMIF(ALIF_Y2019!$I:$I,$B24,ALIF_Y2019!$F:$F) -> 0 | J24: =-SUMIF(ALIF_Y2020!$I:$I,$B24,ALIF_Y2020!$F:$F) -> 0 | K24: =-SUMIF(ALIF_Y2021!$I:$I,$B24,ALIF_Y2021!$F:$F) -> 0 | L24: =-SUMIF(ALIF_Y2022!$I:$I,$B24,ALIF_Y2022!$F:$F) -> 0 | M24: =-SUMIF(ALIF_Y2023!$I:$I,$B24,ALIF_Y2023!$F:$F) -> 0 | N24: =-SUMIF(ALIF_Y2024!$I:$I,$B24,ALIF_Y2024!$F:$F) -> 0 | O24: =-SUMIF(ALIF_Y2025!$I:$I,$B24,ALIF_Y2025!$F:$F) -> 0
B25: Zakat provision | D25: =-SUMIF(ALIF_Y2014!$I:$I,$B25,ALIF_Y2014!$F:$F) -> 1537200 | E25: =-SUMIF(ALIF_Y2015!$I:$I,$B25,ALIF_Y2015!$F:$F) -> 1365110 | F25: =-SUMIF(ALIF_Y2016!$I:$I,$B25,ALIF_Y2016!$F:$F) -> 1200000 | G25: =-SUMIF(ALIF_Y2017!$I:$I,$B25,ALIF_Y2017!$F:$F) -> 1119039 | H25: =-SUMIF(ALIF_Y2018!$I:$I,$B25,ALIF_Y2018!$F:$F) -> 1150000.5 | I25: =-SUMIF(ALIF_Y2019!$I:$I,$B25,ALIF_Y2019!$F:$F) -> 983057 | J25: =-SUMIF(ALIF_Y2020!$I:$I,$B25,ALIF_Y2020!$F:$F) -> 644386 | K25: =-SUMIF(ALIF_Y2021!$I:$I,$B25,ALIF_Y2021!$F:$F) -> 0 | L25: =-SUMIF(ALIF_Y2022!$I:$I,$B25,ALIF_Y2022!$F:$F) -> 0 | M25: =-SUMIF(ALIF_Y2023!$I:$I,$B25,ALIF_Y2023!$F:$F) -> 968047.97 | N25: =-SUMIF(ALIF_Y2024!$I:$I,$B25,ALIF_Y2024!$F:$F) -> 0 | O25: =-SUMIF(ALIF_Y2025!$I:$I,$B25,ALIF_Y2025!$F:$F) -> 0
B26: Tade payables and Accuals & other credit balances | D26: =-SUMIF(ALIF_Y2014!$I:$I,$B26,ALIF_Y2014!$F:$F) -> 2507261 | E26: =-SUMIF(ALIF_Y2015!$I:$I,$B26,ALIF_Y2015!$F:$F) -> 6283439 | F26: =-SUMIF(ALIF_Y2016!$I:$I,$B26,ALIF_Y2016!$F:$F) -> 5444461 | G26: =-SUMIF(ALIF_Y2017!$I:$I,$B26,ALIF_Y2017!$F:$F) -> 6914829 | H26: =-SUMIF(ALIF_Y2018!$I:$I,$B26,ALIF_Y2018!$F:$F) -> 8339707 | I26: =-SUMIF(ALIF_Y2019!$I:$I,$B26,ALIF_Y2019!$F:$F) -> 6947242 | J26: =-SUMIF(ALIF_Y2020!$I:$I,$B26,ALIF_Y2020!$F:$F) -> 9755293 | K26: =-SUMIF(ALIF_Y2021!$I:$I,$B26,ALIF_Y2021!$F:$F) -> 6517602.2 | L26: =-SUMIF(ALIF_Y2022!$I:$I,$B26,ALIF_Y2022!$F:$F) -> 6436834.9 | M26: =-SUMIF(ALIF_Y2023!$I:$I,$B26,ALIF_Y2023!$F:$F) -> 6572651 | N26: =-SUMIF(ALIF_Y2024!$I:$I,$B26,ALIF_Y2024!$F:$F) -> 13430273 | O26: =-SUMIF(ALIF_Y2025!$I:$I,$B26,ALIF_Y2025!$F:$F) -> 24407376
B27: Total current liabilities | D27: =SUM(D23:D26) -> 28942123 | E27: =SUM(E23:E26) -> 19624548 | F27: =SUM(F23:F26) -> 32797032 | G27: =SUM(G23:G26) -> 8033868 | H27: =SUM(H23:H26) -> 70324806 | I27: =SUM(I23:I26) -> 75488656 | J27: =SUM(J23:J26) -> 97469317 | K27: =SUM(K23:K26) -> 99962460 | ... O27: =SUM(O23:O26) -> 2.1780419e+08
B29: Non-current liabilities
B30: Lease liabilities non-current | D30: =-SUMIF(ALIF_Y2014!$I:$I,$B30,ALIF_Y2014!$F:$F) -> 0 | E30: =-SUMIF(ALIF_Y2015!$I:$I,$B30,ALIF_Y2015!$F:$F) -> 0 | F30: =-SUMIF(ALIF_Y2016!$I:$I,$B30,ALIF_Y2016!$F:$F) -> 0 | G30: =-SUMIF(ALIF_Y2017!$I:$I,$B30,ALIF_Y2017!$F:$F) -> 0 | H30: =-SUMIF(ALIF_Y2018!$I:$I,$B30,ALIF_Y2018!$F:$F) -> 0 | I30: =-SUMIF(ALIF_Y2019!$I:$I,$B30,ALIF_Y2019!$F:$F) -> 1874374 | J30: =-SUMIF(ALIF_Y2020!$I:$I,$B30,ALIF_Y2020!$F:$F) -> 1823243.6 | K30: =-SUMIF(ALIF_Y2021!$I:$I,$B30,ALIF_Y2021!$F:$F) -> 1711827 | L30: =-SUMIF(ALIF_Y2022!$I:$I,$B30,ALIF_Y2022!$F:$F) -> 1596797 | M30: =-SUMIF(ALIF_Y2023!$I:$I,$B30,ALIF_Y2023!$F:$F) -> 1505845.1 | N30: =-SUMIF(ALIF_Y2024!$I:$I,$B30,ALIF_Y2024!$F:$F) -> 1399831.1 | O30: =-SUMIF(ALIF_Y2025!$I:$I,$B30,ALIF_Y2025!$F:$F) -> 2585822
B31: Due to related parties | D31: =-SUMIF(ALIF_Y2014!$I:$I,$B31,ALIF_Y2014!$F:$F) -> 0 | E31: =-SUMIF(ALIF_Y2015!$I:$I,$B31,ALIF_Y2015!$F:$F) -> 0 | F31: =-SUMIF(ALIF_Y2016!$I:$I,$B31,ALIF_Y2016!$F:$F) -> 0 | G31: =-SUMIF(ALIF_Y2017!$I:$I,$B31,ALIF_Y2017!$F:$F) -> 31714782 | H31: =-SUMIF(ALIF_Y2018!$I:$I,$B31,ALIF_Y2018!$F:$F) -> 7696296.2 | I31: =-SUMIF(ALIF_Y2019!$I:$I,$B31,ALIF_Y2019!$F:$F) -> 502289.05 | J31: =-SUMIF(ALIF_Y2020!$I:$I,$B31,ALIF_Y2020!$F:$F) -> 277914.95 | K31: =-SUMIF(ALIF_Y2021!$I:$I,$B31,ALIF_Y2021!$F:$F) -> -146154.66 | L31: =-SUMIF(ALIF_Y2022!$I:$I,$B31,ALIF_Y2022!$F:$F) -> 1098996.6 | M31: =-SUMIF(ALIF_Y2023!$I:$I,$B31,ALIF_Y2023!$F:$F) -> -16923360 | N31: =-SUMIF(ALIF_Y2024!$I:$I,$B31,ALIF_Y2024!$F:$F) -> 16103933 | O31: =-SUMIF(ALIF_Y2025!$I:$I,$B31,ALIF_Y2025!$F:$F) -> 30600617
B32: End-of-service indemnities | D32: =-SUMIF(ALIF_Y2014!$I:$I,$B32,ALIF_Y2014!$F:$F) -> 2925857.7 | E32: =-SUMIF(ALIF_Y2015!$I:$I,$B32,ALIF_Y2015!$F:$F) -> 2992687.9 | F32: =-SUMIF(ALIF_Y2016!$I:$I,$B32,ALIF_Y2016!$F:$F) -> 4649375 | G32: =-SUMIF(ALIF_Y2017!$I:$I,$B32,ALIF_Y2017!$F:$F) -> 4847761 | H32: =-SUMIF(ALIF_Y2018!$I:$I,$B32,ALIF_Y2018!$F:$F) -> 4633898 | I32: =-SUMIF(ALIF_Y2019!$I:$I,$B32,ALIF_Y2019!$F:$F) -> 4294641 | J32: =-SUMIF(ALIF_Y2020!$I:$I,$B32,ALIF_Y2020!$F:$F) -> 4405440 | K32: =-SUMIF(ALIF_Y2021!$I:$I,$B32,ALIF_Y2021!$F:$F) -> 3891962 | L32: =-SUMIF(ALIF_Y2022!$I:$I,$B32,ALIF_Y2022!$F:$F) -> 4434767 | M32: =-SUMIF(ALIF_Y2023!$I:$I,$B32,ALIF_Y2023!$F:$F) -> 5799270.3 | N32: =-SUMIF(ALIF_Y2024!$I:$I,$B32,ALIF_Y2024!$F:$F) -> 3409950.9 | O32: =-SUMIF(ALIF_Y2025!$I:$I,$B32,ALIF_Y2025!$F:$F) -> 4431984.9
B33: Provision for evacuation | D33: =-SUMIF(ALIF_Y2014!$I:$I,$B33,ALIF_Y2014!$F:$F) -> 0 | E33: =-SUMIF(ALIF_Y2015!$I:$I,$B33,ALIF_Y2015!$F:$F) -> 0 | F33: =-SUMIF(ALIF_Y2016!$I:$I,$B33,ALIF_Y2016!$F:$F) -> 0 | G33: =-SUMIF(ALIF_Y2017!$I:$I,$B33,ALIF_Y2017!$F:$F) -> 0 | H33: =-SUMIF(ALIF_Y2018!$I:$I,$B33,ALIF_Y2018!$F:$F) -> 4000000 | I33: =-SUMIF(ALIF_Y2019!$I:$I,$B33,ALIF_Y2019!$F:$F) -> 4120000 | J33: =-SUMIF(ALIF_Y2020!$I:$I,$B33,ALIF_Y2020!$F:$F) -> 4214760 | K33: =-SUMIF(ALIF_Y2021!$I:$I,$B33,ALIF_Y2021!$F:$F) -> 4329893.2 | L33: =-SUMIF(ALIF_Y2022!$I:$I,$B33,ALIF_Y2022!$F:$F) -> 4426579.7 | M33: =-SUMIF(ALIF_Y2023!$I:$I,$B33,ALIF_Y2023!$F:$F) -> 4698371.7 | N33: =-SUMIF(ALIF_Y2024!$I:$I,$B33,ALIF_Y2024!$F:$F) -> 4807655.8 | O33: =-SUMIF(ALIF_Y2025!$I:$I,$B33,ALIF_Y2025!$F:$F) -> 4862172.9
B34: Total non-current liabilities | D34: =SUM(D30:D33) -> 2925857.7 | E34: =SUM(E30:E33) -> 2992687.9 | F34: =SUM(F30:F33) -> 4649375 | G34: =SUM(G30:G33) -> 36562543 | H34: =SUM(H30:H33) -> 16330194 | I34: =SUM(I30:I33) -> 10791304 | J34: =SUM(J30:J33) -> 10721359 | K34: =SUM(K30:K33) -> 9787527.6 | ... O34: =SUM(O30:O33) -> 42480597
B35: TOTAL LIABILITES | D35: =D34+D27 -> 31867981 | E35: =E34+E27 -> 22617235 | F35: =F34+F27 -> 37446407 | G35: =G34+G27 -> 44596411 | H35: =H34+H27 -> 86655000 | I35: =I34+I27 -> 86279960 | J35: =J34+J27 -> 1.0819068e+08 | K35: =K34+K27 -> 1.0974999e+08 | ... O35: =O34+O27 -> 2.6028479e+08
B37: Shareholders' equity
B38: Share capital | D38: =-SUMIF(ALIF_Y2014!$I:$I,$B38,ALIF_Y2014!$F:$F) -> 33568250 | E38: =-SUMIF(ALIF_Y2015!$I:$I,$B38,ALIF_Y2015!$F:$F) -> 33568250 | F38: =-SUMIF(ALIF_Y2016!$I:$I,$B38,ALIF_Y2016!$F:$F) -> 33568250 | G38: =-SUMIF(ALIF_Y2017!$I:$I,$B38,ALIF_Y2017!$F:$F) -> 33568250 | H38: =-SUMIF(ALIF_Y2018!$I:$I,$B38,ALIF_Y2018!$F:$F) -> 33568250 | I38: =-SUMIF(ALIF_Y2019!$I:$I,$B38,ALIF_Y2019!$F:$F) -> 33568250 | J38: =-SUMIF(ALIF_Y2020!$I:$I,$B38,ALIF_Y2020!$F:$F) -> 35335000 | K38: =-SUMIF(ALIF_Y2021!$I:$I,$B38,ALIF_Y2021!$F:$F) -> 35335000 | L38: =-SUMIF(ALIF_Y2022!$I:$I,$B38,ALIF_Y2022!$F:$F) -> 35335000 | M38: =-SUMIF(ALIF_Y2023!$I:$I,$B38,ALIF_Y2023!$F:$F) -> 35335000 | N38: =-SUMIF(ALIF_Y2024!$I:$I,$B38,ALIF_Y2024!$F:$F) -> 35335000 | O38: =-SUMIF(ALIF_Y2025!$I:$I,$B38,ALIF_Y2025!$F:$F) -> 35335000
B39: Statutory reserve | D39: =-SUMIF(ALIF_Y2014!$I:$I,$B39,ALIF_Y2014!$F:$F) -> 3512480 | E39: =-SUMIF(ALIF_Y2015!$I:$I,$B39,ALIF_Y2015!$F:$F) -> 4856327 | F39: =-SUMIF(ALIF_Y2016!$I:$I,$B39,ALIF_Y2016!$F:$F) -> 5627620 | G39: =-SUMIF(ALIF_Y2017!$I:$I,$B39,ALIF_Y2017!$F:$F) -> 5627620 | H39: =-SUMIF(ALIF_Y2018!$I:$I,$B39,ALIF_Y2018!$F:$F) -> 6053397 | I39: =-SUMIF(ALIF_Y2019!$I:$I,$B39,ALIF_Y2019!$F:$F) -> 6684528 | J39: =-SUMIF(ALIF_Y2020!$I:$I,$B39,ALIF_Y2020!$F:$F) -> 6684528 | K39: =-SUMIF(ALIF_Y2021!$I:$I,$B39,ALIF_Y2021!$F:$F) -> 7202958 | L39: =-SUMIF(ALIF_Y2022!$I:$I,$B39,ALIF_Y2022!$F:$F) -> 7846137 | M39: =-SUMIF(ALIF_Y2023!$I:$I,$B39,ALIF_Y2023!$F:$F) -> 7846137 | N39: =-SUMIF(ALIF_Y2024!$I:$I,$B39,ALIF_Y2024!$F:$F) -> 7846137 | O39: =-SUMIF(ALIF_Y2025!$I:$I,$B39,ALIF_Y2025!$F:$F) -> 7846137
B40: Retained earnings | D40: =-SUMIF(ALIF_Y2014!$I:$I,$B40,ALIF_Y2014!$F:$F)-SUMIF(ALIF_Y2014!$G:$G,"IS",ALIF_Y2014!$F:$F) -> 35437048 | E40: =-SUMIF(ALIF_Y2015!$I:$I,$B40,ALIF_Y2015!$F:$F)-SUMIF(ALIF_Y2015!$G:$G,"IS",ALIF_Y2015!$F:$F) -> 40958807 | F40: =-SUMIF(ALIF_Y2016!$I:$I,$B40,ALIF_Y2016!$F:$F)-SUMIF(ALIF_Y2016!$G:$G,"IS",ALIF_Y2016!$F:$F) -> 25963821 | G40: =-SUMIF(ALIF_Y2017!$I:$I,$B40,ALIF_Y2017!$F:$F)-SUMIF(ALIF_Y2017!$G:$G,"IS",ALIF_Y2017!$F:$F) -> 25089527 | H40: =-SUMIF(ALIF_Y2018!$I:$I,$B40,ALIF_Y2018!$F:$F)-SUMIF(ALIF_Y2018!$G:$G,"IS",ALIF_Y2018!$F:$F) -> 31662134 | I40: =-SUMIF(ALIF_Y2019!$I:$I,$B40,ALIF_Y2019!$F:$F)-SUMIF(ALIF_Y2019!$G:$G,"IS",ALIF_Y2019!$F:$F) -> 33642416 | J40: =-SUMIF(ALIF_Y2020!$I:$I,$B40,ALIF_Y2020!$F:$F)-SUMIF(ALIF_Y2020!$G:$G,"IS",ALIF_Y2020!$F:$F) -> 12723944 | K40: =-SUMIF(ALIF_Y2021!$I:$I,$B40,ALIF_Y2021!$F:$F)-SUMIF(ALIF_Y2021!$G:$G,"IS",ALIF_Y2021!$F:$F) -> 17758545 | L40: =-SUMIF(ALIF_Y2022!$I:$I,$B40,ALIF_Y2022!$F:$F)-SUMIF(ALIF_Y2022!$G:$G,"IS",ALIF_Y2022!$F:$F) -> 24425366 | M40: =-SUMIF(ALIF_Y2023!$I:$I,$B40,ALIF_Y2023!$F:$F)-SUMIF(ALIF_Y2023!$G:$G,"IS",ALIF_Y2023!$F:$F) -> -11949183 | N40: =-SUMIF(ALIF_Y2024!$I:$I,$B40,ALIF_Y2024!$F:$F)-SUMIF(ALIF_Y2024!$G:$G,"IS",ALIF_Y2024!$F:$F) -> -30717238 | O40: =-SUMIF(ALIF_Y2025!$I:$I,$B40,ALIF_Y2025!$F:$F)-SUMIF(ALIF_Y2025!$G:$G,"IS",ALIF_Y2025!$F:$F) -> -78929334
B41: Additional contribution from shareholders | D41: =-SUMIF(ALIF_Y2014!$I:$I,$B41,ALIF_Y2014!$F:$F) -> 0 | E41: =-SUMIF(ALIF_Y2015!$I:$I,$B41,ALIF_Y2015!$F:$F) -> 0 | F41: =-SUMIF(ALIF_Y2016!$I:$I,$B41,ALIF_Y2016!$F:$F) -> 85866130 | G41: =-SUMIF(ALIF_Y2017!$I:$I,$B41,ALIF_Y2017!$F:$F) -> 85866130 | H41: =-SUMIF(ALIF_Y2018!$I:$I,$B41,ALIF_Y2018!$F:$F) -> 1.0225532e+08 | I41: =-SUMIF(ALIF_Y2019!$I:$I,$B41,ALIF_Y2019!$F:$F) -> 1.0225532e+08 | J41: =-SUMIF(ALIF_Y2020!$I:$I,$B41,ALIF_Y2020!$F:$F) -> 1.0225532e+08 | K41: =-SUMIF(ALIF_Y2021!$I:$I,$B41,ALIF_Y2021!$F:$F) -> 1.0225532e+08 | L41: =-SUMIF(ALIF_Y2022!$I:$I,$B41,ALIF_Y2022!$F:$F) -> 1.0225532e+08 | M41: =-SUMIF(ALIF_Y2023!$I:$I,$B41,ALIF_Y2023!$F:$F) -> 1.0225532e+08 | N41: =-SUMIF(ALIF_Y2024!$I:$I,$B41,ALIF_Y2024!$F:$F) -> 1.0225532e+08 | O41: =-SUMIF(ALIF_Y2025!$I:$I,$B41,ALIF_Y2025!$F:$F) -> 1.0225532e+08
B42: Total shareholders’ equity | D42: =SUM(D38:D41) -> 72517778 | E42: =SUM(E38:E41) -> 79383384 | F42: =SUM(F38:F41) -> 1.5102582e+08 | G42: =SUM(G38:G41) -> 1.5015153e+08 | H42: =SUM(H38:H41) -> 1.735391e+08 | I42: =SUM(I38:I41) -> 1.7615051e+08 | J42: =SUM(J38:J41) -> 1.5699879e+08 | K42: =SUM(K38:K41) -> 1.6255182e+08 | ... O42: =SUM(O38:O41) -> 66507118
B44: TOTAL LIABILITIES AND EQUITY | D44: =D27+D34+D42 -> 1.0438576e+08 | E44: =E27+E34+E42 -> 1.0200062e+08 | F44: =F27+F34+F42 -> 1.8847223e+08 | G44: =G27+G34+G42 -> 1.9474794e+08 | H44: =H27+H34+H42 -> 2.601941e+08 | I44: =I27+I34+I42 -> 2.6243047e+08 | J44: =J27+J34+J42 -> 2.6518946e+08 | K44: =K27+K34+K42 -> 2.7230181e+08 | ... O44: =O27+O34+O42 -> 3.2679191e+08
D46: =D44-D19 -> -3603438.5 | E46: =E44-E19 -> -1318911.2 | F46: =F44-F19 -> -3619649 | G46: =G44-G19 -> -3261022.8 | H46: =H44-H19 -> -485044.33 | I46: =I44-I19 -> -1089346.1 | J46: =J44-J19 -> -1237901.3 | K46: =K44-K19 -> -1339380.2 | ... O46: =O44-O19 -> 1566334.4
B48: Working capital | D48: =D11-D27 -> 59658268 | E48: =E11-E27 -> 56472337 | F48: =F11-F27 -> 46127657 | G48: =G11-G27 -> 73972190 | H48: =H11-H27 -> 49968978 | I48: =I11-I27 -> 43247140 | J48: =J11-J27 -> 28230903 | K48: =K11-K27 -> 36352680 | ... O48: =O11-O27 -> -53264010
B49: Current ratio | D49: =D11/D27 -> 3.0612955 | E49: =E11/E27 -> 3.8776377 | F49: =F11/F27 -> 2.4064583 | G49: =G11/G27 -> 10.207544 | H49: =H11/H27 -> 1.7105455 | I49: =I11/I27 -> 1.5728959 | J49: =J11/J27 -> 1.2896389 | K49: =K11/K27 -> 1.3636633 | ... O49: =O11/O27 -> 0.75545003
...

Sheet Charts_BS

Sheet Charts_P&L

Sheet P&L_2014-2025
A1: AIMS INDUSTRIAL
A2: Profit & Loss
A3: Y2014 - Y2025 | C3: 2 | D3: 3 | E3: 4 | F3: 5 | G3: 6 | H3: 7 | I3: 8 | J3: 9 | K3: 10 | L3: 11
C5: Y2014 | D5: Y2015 | E5: Y2016 | F5: Y2017 | G5: Y2018 | H5: Y2019 | I5: Y2020 | J5: Y2021 | K5: Y2022 | L5: Y2023 | M5: Y2024 | N5: Y2025
A6: Tons | C6: =C8/C7 -> 23036.583 | D6: 31426 | E6: 32014 | F6: 29528 | G6: 28812 | H6: 38145 | I6: 36751 | J6: 37605 | K6: 37298 | L6: 24159 | M6: 35702 | N6: 45159
A7: Price | C7: 5815.7681 | D7: =D8/D6 -> 3482.599 | E7: =E8/E6 -> 2741.5394 | F7: =F8/F6 -> 3152.215 | G7: =G8/G6 -> 3727.9615 | H7: =H8/H6 -> 3829.6435 | I7: =I8/I6 -> 3444.8813 | J7: =J8/J6 -> 4856.2358 | K7: =K8/K6 -> 5951.1168 | ... N7: =N8/N6 -> 3429.951
A8: Sales | C8: =-SUMIF(ALIF_Y2014!I:I,A8,ALIF_Y2014!F:F) -> 1.3397542e+08 | D8: =-SUMIF(ALIF_Y2015!I:I,A8,ALIF_Y2015!F:F) -> 1.0944416e+08 | E8: =-SUMIF(ALIF_Y2016!I:I,A8,ALIF_Y2016!F:F) -> 87767643 | F8: =-SUMIF(ALIF_Y2017!I:I,A8,ALIF_Y2017!F:F) -> 93078605 | G8: =-SUMIF(ALIF_Y2018!I:I,A8,ALIF_Y2018!F:F) -> 1.0741003e+08 | H8: =-SUMIF(ALIF_Y2019!I:I,A8,ALIF_Y2019!F:F) -> 1.4608175e+08 | I8: =-SUMIF(ALIF_Y2020!I:I,A8,ALIF_Y2020!F:F) -> 1.2660283e+08 | J8: =-SUMIF(ALIF_Y2021!I:I,A8,ALIF_Y2021!F:F) -> 1.8261875e+08 | K8: =-SUMIF(ALIF_Y2022!I:I,A8,ALIF_Y2022!F:F) -> 2.2196476e+08 | L8: =-SUMIF(ALIF_Y2023!I:I,A8,ALIF_Y2023!F:F) -> 1.0420051e+08 | M8: =-SUMIF(ALIF_Y2024!I:I,A8,ALIF_Y2024!F:F) -> 1.3521087e+08 | N8: =-SUMIF(ALIF_Y2025!I:I,A8,ALIF_Y2025!F:F) -> 1.5489316e+08
A10: Raw materials | C10: =SUMIF(ALIF_Y2014!I:I,A10,ALIF_Y2014!F:F) -> 81941049 | D10: =SUMIF(ALIF_Y2015!I:I,A10,ALIF_Y2015!F:F) -> 65904068 | E10: =SUMIF(ALIF_Y2016!I:I,A10,ALIF_Y2016!F:F) -> 55179706 | F10: =SUMIF(ALIF_Y2017!I:I,A10,ALIF_Y2017!F:F) -> 58214236 | G10: =SUMIF(ALIF_Y2018!I:I,A10,ALIF_Y2018!F:F) -> 75159713 | H10: =SUMIF(ALIF_Y2019!I:I,A10,ALIF_Y2019!F:F) -> 1.0180015e+08 | I10: =SUMIF(ALIF_Y2020!I:I,A10,ALIF_Y2020!F:F) -> 1.0098846e+08 | J10: =SUMIF(ALIF_Y2021!I:I,A10,ALIF_Y2021!F:F) -> 1.2845715e+08 | K10: =SUMIF(ALIF_Y2022!I:I,A10,ALIF_Y2022!F:F) -> 1.5899362e+08 | L10: =SUMIF(ALIF_Y2023!I:I,A10,ALIF_Y2023!F:F) -> 86519534 | M10: =SUMIF(ALIF_Y2024!I:I,A10,ALIF_Y2024!F:F) -> 1.0646571e+08 | N10: =SUMIF(ALIF_Y2025!I:I,A10,ALIF_Y2025!F:F) -> 1.1426246e+08
A11: Direct Labor | C11: =SUMIF(ALIF_Y2014!I:I,A11,ALIF_Y2014!F:F) -> 10110578 | D11: =SUMIF(ALIF_Y2015!I:I,A11,ALIF_Y2015!F:F) -> 4964584.6 | E11: =SUMIF(ALIF_Y2016!I:I,A11,ALIF_Y2016!F:F) -> 2752188.9 | F11: =SUMIF(ALIF_Y2017!I:I,A11,ALIF_Y2017!F:F) -> 8076733.4 | G11: =SUMIF(ALIF_Y2018!I:I,A11,ALIF_Y2018!F:F) -> 4690498.9 | H11: =SUMIF(ALIF_Y2019!I:I,A11,ALIF_Y2019!F:F) -> 4737194 | I11: =SUMIF(ALIF_Y2020!I:I,A11,ALIF_Y2020!F:F) -> 4616680.1 | J11: =SUMIF(ALIF_Y2021!I:I,A11,ALIF_Y2021!F:F) -> 6113549 | K11: =SUMIF(ALIF_Y2022!I:I,A11,ALIF_Y2022!F:F) -> 7571448.7 | L11: =SUMIF(ALIF_Y2023!I:I,A11,ALIF_Y2023!F:F) -> 4537898.5 | M11: =SUMIF(ALIF_Y2024!I:I,A11,ALIF_Y2024!F:F) -> 5342594.8 | N11: =SUMIF(ALIF_Y2025!I:I,A11,ALIF_Y2025!F:F) -> 14662273
A12: Freight expenses | C12: =SUMIF(ALIF_Y2014!I:I,A12,ALIF_Y2014!F:F) -> 2673874.8 | D12: =SUMIF(ALIF_Y2015!I:I,A12,ALIF_Y2015!F:F) -> 2734734.3 | E12: =SUMIF(ALIF_Y2016!I:I,A12,ALIF_Y2016!F:F) -> 2666816.5 | F12: =SUMIF(ALIF_Y2017!I:I,A12,ALIF_Y2017!F:F) -> 2233233.6 | G12: =SUMIF(ALIF_Y2018!I:I,A12,ALIF_Y2018!F:F) -> 3256415.5 | H12: =SUMIF(ALIF_Y2019!I:I,A12,ALIF_Y2019!F:F) -> 3483379.7 | I12: =SUMIF(ALIF_Y2020!I:I,A12,ALIF_Y2020!F:F) -> 2692057.3 | J12: =SUMIF(ALIF_Y2021!I:I,A12,ALIF_Y2021!F:F) -> 2800211.2 | K12: =SUMIF(ALIF_Y2022!I:I,A12,ALIF_Y2022!F:F) -> 2728489.4 | L12: =SUMIF(ALIF_Y2023!I:I,A12,ALIF_Y2023!F:F) -> 2712576.4 | M12: =SUMIF(ALIF_Y2024!I:I,A12,ALIF_Y2024!F:F) -> 2003043.6 | N12: =SUMIF(ALIF_Y2025!I:I,A12,ALIF_Y2025!F:F) -> 2233578.2
A13: Customs duties and clearances | C13: =SUMIF(ALIF_Y2014!I:I,A13,ALIF_Y2014!F:F) -> 0 | D13: =SUMIF(ALIF_Y2015!I:I,A13,ALIF_Y2015!F:F) -> 0 | E13: =SUMIF(ALIF_Y2016!I:I,A13,ALIF_Y2016!F:F) -> 0 | F13: =SUMIF(ALIF_Y2017!I:I,A13,ALIF_Y2017!F:F) -> 0 | G13: =SUMIF(ALIF_Y2018!I:I,A13,ALIF_Y2018!F:F) -> 0 | H13: =SUMIF(ALIF_Y2019!I:I,A13,ALIF_Y2019!F:F) -> 0 | I13: =SUMIF(ALIF_Y2020!I:I,A13,ALIF_Y2020!F:F) -> 0 | J13: =SUMIF(ALIF_Y2021!I:I,A13,ALIF_Y2021!F:F) -> 0 | K13: =SUMIF(ALIF_Y2022!I:I,A13,ALIF_Y2022!F:F) -> 0 | L13: =SUMIF(ALIF_Y2023!I:I,A13,ALIF_Y2023!F:F) -> 0 | M13: =SUMIF(ALIF_Y2024!I:I,A13,ALIF_Y2024!F:F) -> 0 | N13: =SUMIF(ALIF_Y2025!I:I,A13,ALIF_Y2025!F:F) -> -1.3969839e-09
A14: Depreciation - Machines | C14: =SUMIF(ALIF_Y2014!I:I,A14,ALIF_Y2014!F:F) -> 2954190.5 | D14: =SUMIF(ALIF_Y2015!I:I,A14,ALIF_Y2015!F:F) -> 3165403.4 | E14: =SUMIF(ALIF_Y2016!I:I,A14,ALIF_Y2016!F:F) -> 3435007.7 | F14: =SUMIF(ALIF_Y2017!I:I,A14,ALIF_Y2017!F:F) -> 3533037.4 | G14: =SUMIF(ALIF_Y2018!I:I,A14,ALIF_Y2018!F:F) -> 2198099 | H14: =SUMIF(ALIF_Y2019!I:I,A14,ALIF_Y2019!F:F) -> 3638104.1 | I14: =SUMIF(ALIF_Y2020!I:I,A14,ALIF_Y2020!F:F) -> 3256640.8 | J14: =SUMIF(ALIF_Y2021!I:I,A14,ALIF_Y2021!F:F) -> 3446969.6 | K14: =SUMIF(ALIF_Y2022!I:I,A14,ALIF_Y2022!F:F) -> 3787622.1 | L14: =SUMIF(ALIF_Y2023!I:I,A14,ALIF_Y2023!F:F) -> 3892923.1 | M14: =SUMIF(ALIF_Y2024!I:I,A14,ALIF_Y2024!F:F) -> 4522894.6 | N14: =SUMIF(ALIF_Y2025!I:I,A14,ALIF_Y2025!F:F) -> 7355690.5
A15: Overhead - Labor Cost | C15: =SUMIF(ALIF_Y2014!I:I,A15,ALIF_Y2014!F:F) -> 2434320.9 | D15: =SUMIF(ALIF_Y2015!I:I,A15,ALIF_Y2015!F:F) -> 2420064 | E15: =SUMIF(ALIF_Y2016!I:I,A15,ALIF_Y2016!F:F) -> 2254831.1 | F15: =SUMIF(ALIF_Y2017!I:I,A15,ALIF_Y2017!F:F) -> 2034286.4 | G15: =SUMIF(ALIF_Y2018!I:I,A15,ALIF_Y2018!F:F) -> 1095147.3 | H15: =SUMIF(ALIF_Y2019!I:I,A15,ALIF_Y2019!F:F) -> 3949079.1 | I15: =SUMIF(ALIF_Y2020!I:I,A15,ALIF_Y2020!F:F) -> 4120005 | J15: =SUMIF(ALIF_Y2021!I:I,A15,ALIF_Y2021!F:F) -> 6548586.4 | K15: =SUMIF(ALIF_Y2022!I:I,A15,ALIF_Y2022!F:F) -> 7463313.9 | L15: =SUMIF(ALIF_Y2023!I:I,A15,ALIF_Y2023!F:F) -> 5122044.2 | M15: =SUMIF(ALIF_Y2024!I:I,A15,ALIF_Y2024!F:F) -> 4990962.7 | N15: =SUMIF(ALIF_Y2025!I:I,A15,ALIF_Y2025!F:F) -> 2551484.3
A16: Overhead - Consumables & SP | C16: =SUMIF(ALIF_Y2014!I:I,A16,ALIF_Y2014!F:F) -> 3476434.1 | D16: =SUMIF(ALIF_Y2015!I:I,A16,ALIF_Y2015!F:F) -> 4063793.3 | E16: =SUMIF(ALIF_Y2016!I:I,A16,ALIF_Y2016!F:F) -> 3017957.2 | F16: =SUMIF(ALIF_Y2017!I:I,A16,ALIF_Y2017!F:F) -> 2258622.4 | G16: =SUMIF(ALIF_Y2018!I:I,A16,ALIF_Y2018!F:F) -> 1475017.7 | H16: =SUMIF(ALIF_Y2019!I:I,A16,ALIF_Y2019!F:F) -> 3632906.7 | I16: =SUMIF(ALIF_Y2020!I:I,A16,ALIF_Y2020!F:F) -> 4290617.2 | J16: =SUMIF(ALIF_Y2021!I:I,A16,ALIF_Y2021!F:F) -> 6410977.4 | K16: =SUMIF(ALIF_Y2022!I:I,A16,ALIF_Y2022!F:F) -> 9548411.9 | L16: =SUMIF(ALIF_Y2023!I:I,A16,ALIF_Y2023!F:F) -> 4461814.3 | M16: =SUMIF(ALIF_Y2024!I:I,A16,ALIF_Y2024!F:F) -> 2688304.1 | N16: =SUMIF(ALIF_Y2025!I:I,A16,ALIF_Y2025!F:F) -> 1875073.1
A17: Overhead - Utility | C17: =SUMIF(ALIF_Y2014!I:I,A17,ALIF_Y2014!F:F) -> 1517090.9 | D17: =SUMIF(ALIF_Y2015!I:I,A17,ALIF_Y2015!F:F) -> 1890240.9 | E17: =SUMIF(ALIF_Y2016!I:I,A17,ALIF_Y2016!F:F) -> 2206670.1 | F17: =SUMIF(ALIF_Y2017!I:I,A17,ALIF_Y2017!F:F) -> 1979114.8 | G17: =SUMIF(ALIF_Y2018!I:I,A17,ALIF_Y2018!F:F) -> 878697.03 | H17: =SUMIF(ALIF_Y2019!I:I,A17,ALIF_Y2019!F:F) -> 2551280.2 | I17: =SUMIF(ALIF_Y2020!I:I,A17,ALIF_Y2020!F:F) -> 2434106.6 | J17: =SUMIF(ALIF_Y2021!I:I,A17,ALIF_Y2021!F:F) -> 2828304.4 | K17: =SUMIF(ALIF_Y2022!I:I,A17,ALIF_Y2022!F:F) -> 2591967.2 | L17: =SUMIF(ALIF_Y2023!I:I,A17,ALIF_Y2023!F:F) -> 1657016 | M17: =SUMIF(ALIF_Y2024!I:I,A17,ALIF_Y2024!F:F) -> 2070169 | N17: =SUMIF(ALIF_Y2025!I:I,A17,ALIF_Y2025!F:F) -> 2881316.6
A18: Overhead - R&M | C18: =SUMIF(ALIF_Y2014!I:I,A18,ALIF_Y2014!F:F) -> 257436.95 | D18: =SUMIF(ALIF_Y2015!I:I,A18,ALIF_Y2015!F:F) -> 138250 | E18: =SUMIF(ALIF_Y2016!I:I,A18,ALIF_Y2016!F:F) -> 63418 | F18: =SUMIF(ALIF_Y2017!I:I,A18,ALIF_Y2017!F:F) -> 203768.74 | G18: =SUMIF(ALIF_Y2018!I:I,A18,ALIF_Y2018!F:F) -> 78876.841 | H18: =SUMIF(ALIF_Y2019!I:I,A18,ALIF_Y2019!F:F) -> 307100.91 | I18: =SUMIF(ALIF_Y2020!I:I,A18,ALIF_Y2020!F:F) -> 466866.55 | J18: =SUMIF(ALIF_Y2021!I:I,A18,ALIF_Y2021!F:F) -> 1765300 | K18: =SUMIF(ALIF_Y2022!I:I,A18,ALIF_Y2022!F:F) -> 1776877.6 | L18: =SUMIF(ALIF_Y2023!I:I,A18,ALIF_Y2023!F:F) -> 285381.59 | M18: =SUMIF(ALIF_Y2024!I:I,A18,ALIF_Y2024!F:F) -> 1285902.7 | N18: =SUMIF(ALIF_Y2025!I:I,A18,ALIF_Y2025!F:F) -> 7264252.2
A19: Overhead - Rent | C19: =SUMIF(ALIF_Y2014!I:I,A19,ALIF_Y2014!F:F) -> 1371118.4 | D19: =SUMIF(ALIF_Y2015!I:I,A19,ALIF_Y2015!F:F) -> 1515740.4 | E19: =SUMIF(ALIF_Y2016!I:I,A19,ALIF_Y2016!F:F) -> 1491085.3 | F19: =SUMIF(ALIF_Y2017!I:I,A19,ALIF_Y2017!F:F) -> 790799.6 | G19: =SUMIF(ALIF_Y2018!I:I,A19,ALIF_Y2018!F:F) -> 211393.9 | H19: =SUMIF(ALIF_Y2019!I:I,A19,ALIF_Y2019!F:F) -> 465257.95 | I19: =SUMIF(ALIF_Y2020!I:I,A19,ALIF_Y2020!F:F) -> 319821.65 | J19: =SUMIF(ALIF_Y2021!I:I,A19,ALIF_Y2021!F:F) -> 265999.92 | K19: =SUMIF(ALIF_Y2022!I:I,A19,ALIF_Y2022!F:F) -> 275000 | L19: =SUMIF(ALIF_Y2023!I:I,A19,ALIF_Y2023!F:F) -> 277040 | M19: =SUMIF(ALIF_Y2024!I:I,A19,ALIF_Y2024!F:F) -> 244841.6 | N19: =SUMIF(ALIF_Y2025!I:I,A19,ALIF_Y2025!F:F) -> 413654.01
A20: Overhead - Rent Labor | C20: =SUMIF(ALIF_Y2014!I:I,A20,ALIF_Y2014!F:F) -> 0 | D20: =SUMIF(ALIF_Y2015!I:I,A20,ALIF_Y2015!F:F) -> 0 | E20: =SUMIF(ALIF_Y2016!I:I,A20,ALIF_Y2016!F:F) -> 0 | F20: =SUMIF(ALIF_Y2017!I:I,A20,ALIF_Y2017!F:F) -> 0 | G20: =SUMIF(ALIF_Y2018!I:I,A20,ALIF_Y2018!F:F) -> 0 | H20: =SUMIF(ALIF_Y2019!I:I,A20,ALIF_Y2019!F:F) -> 0 | I20: =SUMIF(ALIF_Y2020!I:I,A20,ALIF_Y2020!F:F) -> 0 | J20: =SUMIF(ALIF_Y2021!I:I,A20,ALIF_Y2021!F:F) -> 0 | K20: =SUMIF(ALIF_Y2022!I:I,A20,ALIF_Y2022!F:F) -> 0 | L20: =SUMIF(ALIF_Y2023!I:I,A20,ALIF_Y2023!F:F) -> 518208 | M20: =SUMIF(ALIF_Y2024!I:I,A20,ALIF_Y2024!F:F) -> 2924648.8 | N20: =SUMIF(ALIF_Y2025!I:I,A20,ALIF_Y2025!F:F) -> 3329353.6
A22: Cost of Sales | C22: =SUM(C10:C21) -> 1.0673609e+08 | D22: =SUM(D10:D21) -> 86796879 | E22: =SUM(E10:E21) -> 73067681 | F22: =SUM(F10:F21) -> 79323832 | G22: =SUM(G10:G21) -> 89043859 | H22: =SUM(H10:H21) -> 1.2456445e+08 | I22: =SUM(I10:I21) -> 1.2318526e+08 | J22: =SUM(J10:J21) -> 1.5863705e+08 | ... N22: =SUM(N10:N21) -> 1.5682913e+08
A24: GROSS PROFIT | C24: =C8-C22 -> 27239331 | D24: =D8-D22 -> 22647279 | E24: =E8-E22 -> 14699962 | F24: =F8-F22 -> 13754773 | G24: =G8-G22 -> 18366166 | H24: =H8-H22 -> 21517296 | I24: =I8-I22 -> 3417578.8 | J24: =J8-J22 -> 23981696 | ... N24: =N8-N22 -> -1935975.4
C25: =C24/C8 -> 0.20331588 | D25: =D24/D8 -> 0.20692999 | E25: =E24/E8 -> 0.16748726 | F25: =F24/F8 -> 0.14777588 | G25: =G24/G8 -> 0.17099117 | H25: =H24/H8 -> 0.14729627 | I25: =I24/I8 -> 0.026994489 | J25: =J24/J8 -> 0.13132111 | ... N25: =N24/N8 -> -0.012498779
A27: Advertising and promotion expenses | C27: =SUMIF(ALIF_Y2014!I:I,A27,ALIF_Y2014!F:F) -> 10844 | D27: =SUMIF(ALIF_Y2015!I:I,A27,ALIF_Y2015!F:F) -> 67555 | E27: =SUMIF(ALIF_Y2016!I:I,A27,ALIF_Y2016!F:F) -> 5162 | F27: =SUMIF(ALIF_Y2017!I:I,A27,ALIF_Y2017!F:F) -> 35415.37 | G27: =SUMIF(ALIF_Y2018!I:I,A27,ALIF_Y2018!F:F) -> 82674.032 | H27: =SUMIF(ALIF_Y2019!I:I,A27,ALIF_Y2019!F:F) -> 48665.419 | I27: =SUMIF(ALIF_Y2020!I:I,A27,ALIF_Y2020!F:F) -> 4000 | J27: =SUMIF(ALIF_Y2021!I:I,A27,ALIF_Y2021!F:F) -> 245 | K27: =SUMIF(ALIF_Y2022!I:I,A27,ALIF_Y2022!F:F) -> 95633.99 | L27: =SUMIF(ALIF_Y2023!I:I,A27,ALIF_Y2023!F:F) -> 127136.29 | M27: =SUMIF(ALIF_Y2024!I:I,A27,ALIF_Y2024!F:F) -> 173026.79 | N27: =SUMIF(ALIF_Y2025!I:I,A27,ALIF_Y2025!F:F) -> 52325.74
A28: Exhibitions | C28: =SUMIF(ALIF_Y2014!I:I,A28,ALIF_Y2014!F:F) -> 0 | D28: =SUMIF(ALIF_Y2015!I:I,A28,ALIF_Y2015!F:F) -> 0 | E28: =SUMIF(ALIF_Y2016!I:I,A28,ALIF_Y2016!F:F) -> 0 | F28: =SUMIF(ALIF_Y2017!I:I,A28,ALIF_Y2017!F:F) -> 0 | G28: =SUMIF(ALIF_Y2018!I:I,A28,ALIF_Y2018!F:F) -> 0 | H28: =SUMIF(ALIF_Y2019!I:I,A28,ALIF_Y2019!F:F) -> 38150 | I28: =SUMIF(ALIF_Y2020!I:I,A28,ALIF_Y2020!F:F) -> 0 | J28: =SUMIF(ALIF_Y2021!I:I,A28,ALIF_Y2021!F:F) -> 1315 | K28: =SUMIF(ALIF_Y2022!I:I,A28,ALIF_Y2022!F:F) -> 96132.78 | L28: =SUMIF(ALIF_Y2023!I:I,A28,ALIF_Y2023!F:F) -> 61539 | M28: =SUMIF(ALIF_Y2024!I:I,A28,ALIF_Y2024!F:F) -> 656254.1 | N28: =SUMIF(ALIF_Y2025!I:I,A28,ALIF_Y2025!F:F) -> 1276853.5
A29: Commission expenses | C29: =SUMIF(ALIF_Y2014!I:I,A29,ALIF_Y2014!F:F) -> 221073.86 | D29: =SUMIF(ALIF_Y2015!I:I,A29,ALIF_Y2015!F:F) -> 211475.23 | E29: =SUMIF(ALIF_Y2016!I:I,A29,ALIF_Y2016!F:F) -> 170392 | F29: =SUMIF(ALIF_Y2017!I:I,A29,ALIF_Y2017!F:F) -> 239089.32 | G29: =SUMIF(ALIF_Y2018!I:I,A29,ALIF_Y2018!F:F) -> 184849.25 | H29: =SUMIF(ALIF_Y2019!I:I,A29,ALIF_Y2019!F:F) -> 222802.95 | I29: =SUMIF(ALIF_Y2020!I:I,A29,ALIF_Y2020!F:F) -> 254893.24 | J29: =SUMIF(ALIF_Y2021!I:I,A29,ALIF_Y2021!F:F) -> 332942.77 | K29: =SUMIF(ALIF_Y2022!I:I,A29,ALIF_Y2022!F:F) -> 262263 | L29: =SUMIF(ALIF_Y2023!I:I,A29,ALIF_Y2023!F:F) -> 43952.72 | M29: =SUMIF(ALIF_Y2024!I:I,A29,ALIF_Y2024!F:F) -> 38359.55 | N29: =SUMIF(ALIF_Y2025!I:I,A29,ALIF_Y2025!F:F) -> 5036
A30: Buffet expenses | C30: =SUMIF(ALIF_Y2014!I:I,A30,ALIF_Y2014!F:F) -> 24136 | D30: =SUMIF(ALIF_Y2015!I:I,A30,ALIF_Y2015!F:F) -> 49422 | E30: =SUMIF(ALIF_Y2016!I:I,A30,ALIF_Y2016!F:F) -> 23617 | F30: =SUMIF(ALIF_Y2017!I:I,A30,ALIF_Y2017!F:F) -> 12728.2 | G30: =SUMIF(ALIF_Y2018!I:I,A30,ALIF_Y2018!F:F) -> 38545.124 | H30: =SUMIF(ALIF_Y2019!I:I,A30,ALIF_Y2019!F:F) -> 30691.55 | I30: =SUMIF(ALIF_Y2020!I:I,A30,ALIF_Y2020!F:F) -> 44987.73 | J30: =SUMIF(ALIF_Y2021!I:I,A30,ALIF_Y2021!F:F) -> 44509.047 | K30: =SUMIF(ALIF_Y2022!I:I,A30,ALIF_Y2022!F:F) -> 46729.389 | L30: =SUMIF(ALIF_Y2023!I:I,A30,ALIF_Y2023!F:F) -> 8770.327 | M30: =SUMIF(ALIF_Y2024!I:I,A30,ALIF_Y2024!F:F) -> 112372.72 | N30: =SUMIF(ALIF_Y2025!I:I,A30,ALIF_Y2025!F:F) -> 279488.05
A32: Selling and Distribution | C32: =SUM(C27:C31) -> 256053.86 | D32: =SUM(D27:D31) -> 328452.23 | E32: =SUM(E27:E31) -> 199171 | F32: =SUM(F27:F31) -> 287232.89 | G32: =SUM(G27:G31) -> 306068.41 | H32: =SUM(H27:H31) -> 340309.92 | I32: =SUM(I27:I31) -> 303880.97 | J32: =SUM(J27:J31) -> 379011.82 | ... N32: =SUM(N27:N31) -> 1613703.3
A34: Salaries and wages | C34: =SUMIF(ALIF_Y2014!I:I,A34,ALIF_Y2014!F:F) -> 6363603.8 | D34: =SUMIF(ALIF_Y2015!I:I,A34,ALIF_Y2015!F:F) -> 5731816.7 | E34: =SUMIF(ALIF_Y2016!I:I,A34,ALIF_Y2016!F:F) -> 5700243.6 | F34: =SUMIF(ALIF_Y2017!I:I,A34,ALIF_Y2017!F:F) -> 7742150.8 | G34: =SUMIF(ALIF_Y2018!I:I,A34,ALIF_Y2018!F:F) -> 7523616.8 | H34: =SUMIF(ALIF_Y2019!I:I,A34,ALIF_Y2019!F:F) -> 8539362.4 | I34: =SUMIF(ALIF_Y2020!I:I,A34,ALIF_Y2020!F:F) -> 10507908 | J34: =SUMIF(ALIF_Y2021!I:I,A34,ALIF_Y2021!F:F) -> 11276241 | K34: =SUMIF(ALIF_Y2022!I:I,A34,ALIF_Y2022!F:F) -> 10667360 | L34: =SUMIF(ALIF_Y2023!I:I,A34,ALIF_Y2023!F:F) -> 10673402 | M34: =SUMIF(ALIF_Y2024!I:I,A34,ALIF_Y2024!F:F) -> 10184021 | N34: =SUMIF(ALIF_Y2025!I:I,A34,ALIF_Y2025!F:F) -> 23383962
A35: Utilities | C35: =SUMIF(ALIF_Y2014!I:I,A35,ALIF_Y2014!F:F) -> 452003.42 | D35: =SUMIF(ALIF_Y2015!I:I,A35,ALIF_Y2015!F:F) -> 482714.05 | E35: =SUMIF(ALIF_Y2016!I:I,A35,ALIF_Y2016!F:F) -> 550372.54 | F35: =SUMIF(ALIF_Y2017!I:I,A35,ALIF_Y2017!F:F) -> 512953.74 | G35: =SUMIF(ALIF_Y2018!I:I,A35,ALIF_Y2018!F:F) -> 979494.06 | H35: =SUMIF(ALIF_Y2019!I:I,A35,ALIF_Y2019!F:F) -> 1067033.7 | I35: =SUMIF(ALIF_Y2020!I:I,A35,ALIF_Y2020!F:F) -> 1391075.6 | J35: =SUMIF(ALIF_Y2021!I:I,A35,ALIF_Y2021!F:F) -> 1172434.6 | K35: =SUMIF(ALIF_Y2022!I:I,A35,ALIF_Y2022!F:F) -> 1350946.7 | L35: =SUMIF(ALIF_Y2023!I:I,A35,ALIF_Y2023!F:F) -> 606309.52 | M35: =SUMIF(ALIF_Y2024!I:I,A35,ALIF_Y2024!F:F) -> 1013970 | N35: =SUMIF(ALIF_Y2025!I:I,A35,ALIF_Y2025!F:F) -> 753096.56
A36: Business travel | C36: =SUMIF(ALIF_Y2014!I:I,A36,ALIF_Y2014!F:F) -> 324499 | D36: =SUMIF(ALIF_Y2015!I:I,A36,ALIF_Y2015!F:F) -> 213428 | E36: =SUMIF(ALIF_Y2016!I:I,A36,ALIF_Y2016!F:F) -> 97884.22 | F36: =SUMIF(ALIF_Y2017!I:I,A36,ALIF_Y2017!F:F) -> 98488.72 | G36: =SUMIF(ALIF_Y2018!I:I,A36,ALIF_Y2018!F:F) -> 334049.23 | H36: =SUMIF(ALIF_Y2019!I:I,A36,ALIF_Y2019!F:F) -> 342874.68 | I36: =SUMIF(ALIF_Y2020!I:I,A36,ALIF_Y2020!F:F) -> 78102.23 | J36: =SUMIF(ALIF_Y2021!I:I,A36,ALIF_Y2021!F:F) -> 65074.312 | K36: =SUMIF(ALIF_Y2022!I:I,A36,ALIF_Y2022!F:F) -> 163076.27 | L36: =SUMIF(ALIF_Y2023!I:I,A36,ALIF_Y2023!F:F) -> 326944.08 | M36: =SUMIF(ALIF_Y2024!I:I,A36,ALIF_Y2024!F:F) -> 1176775.5 | N36: =SUMIF(ALIF_Y2025!I:I,A36,ALIF_Y2025!F:F) -> 736726.41
A37: Training | C37: =SUMIF(ALIF_Y2014!I:I,A37,ALIF_Y2014!F:F) -> 0 | D37: =SUMIF(ALIF_Y2015!I:I,A37,ALIF_Y2015!F:F) -> 5707.643 | E37: =SUMIF(ALIF_Y2016!I:I,A37,ALIF_Y2016!F:F) -> 0 | F37: =SUMIF(ALIF_Y2017!I:I,A37,ALIF_Y2017!F:F) -> 0 | G37: =SUMIF(ALIF_Y2018!I:I,A37,ALIF_Y2018!F:F) -> 0 | H37: =SUMIF(ALIF_Y2019!I:I,A37,ALIF_Y2019!F:F) -> 38300 | I37: =SUMIF(ALIF_Y2020!I:I,A37,ALIF_Y2020!F:F) -> 40087 | J37: =SUMIF(ALIF_Y2021!I:I,A37,ALIF_Y2021!F:F) -> 121235.63 | K37: =SUMIF(ALIF_Y2022!I:I,A37,ALIF_Y2022!F:F) -> 74764 | L37: =SUMIF(ALIF_Y2023!I:I,A37,ALIF_Y2023!F:F) -> 3329 | M37: =SUMIF(ALIF_Y2024!I:I,A37,ALIF_Y2024!F:F) -> 441573.53 | N37: =SUMIF(ALIF_Y2025!I:I,A37,ALIF_Y2025!F:F) -> 95706.072
A38: IT expenses | C38: =SUMIF(ALIF_Y2014!I:I,A38,ALIF_Y2014!F:F) -> 47876.31 | D38: =SUMIF(ALIF_Y2015!I:I,A38,ALIF_Y2015!F:F) -> 61858.551 | E38: =SUMIF(ALIF_Y2016!I:I,A38,ALIF_Y2016!F:F) -> 68446.898 | F38: =SUMIF(ALIF_Y2017!I:I,A38,ALIF_Y2017!F:F) -> 83539.5 | G38: =SUMIF(ALIF_Y2018!I:I,A38,ALIF_Y2018!F:F) -> 193976.31 | H38: =SUMIF(ALIF_Y2019!I:I,A38,ALIF_Y2019!F:F) -> 173017.55 | I38: =SUMIF(ALIF_Y2020!I:I,A38,ALIF_Y2020!F:F) -> 347776.16 | J38: =SUMIF(ALIF_Y2021!I:I,A38,ALIF_Y2021!F:F) -> 193144.23 | K38: =SUMIF(ALIF_Y2022!I:I,A38,ALIF_Y2022!F:F) -> 699621.14 | L38: =SUMIF(ALIF_Y2023!I:I,A38,ALIF_Y2023!F:F) -> 757807.59 | M38: =SUMIF(ALIF_Y2024!I:I,A38,ALIF_Y2024!F:F) -> 690317.47 | N38: =SUMIF(ALIF_Y2025!I:I,A38,ALIF_Y2025!F:F) -> 706542.29
A39: Govt license and fees (including modon) | C39: =SUMIF(ALIF_Y2014!I:I,A39,ALIF_Y2014!F:F) -> 497207 | D39: =SUMIF(ALIF_Y2015!I:I,A39,ALIF_Y2015!F:F) -> 594070.73 | E39: =SUMIF(ALIF_Y2016!I:I,A39,ALIF_Y2016!F:F) -> 881628.04 | F39: =SUMIF(ALIF_Y2017!I:I,A39,ALIF_Y2017!F:F) -> 878404.02 | G39: =SUMIF(ALIF_Y2018!I:I,A39,ALIF_Y2018!F:F) -> 798554.73 | H39: =SUMIF(ALIF_Y2019!I:I,A39,ALIF_Y2019!F:F) -> 721606.55 | I39: =SUMIF(ALIF_Y2020!I:I,A39,ALIF_Y2020!F:F) -> 2172417 | J39: =SUMIF(ALIF_Y2021!I:I,A39,ALIF_Y2021!F:F) -> 952190.3 | K39: =SUMIF(ALIF_Y2022!I:I,A39,ALIF_Y2022!F:F) -> 518370.67 | L39: =SUMIF(ALIF_Y2023!I:I,A39,ALIF_Y2023!F:F) -> 660248.72 | M39: =SUMIF(ALIF_Y2024!I:I,A39,ALIF_Y2024!F:F) -> 689064.96 | N39: =SUMIF(ALIF_Y2025!I:I,A39,ALIF_Y2025!F:F) -> 1035438.7
A40: Rent | C40: =SUMIF(ALIF_Y2014!I:I,A40,ALIF_Y2014!F:F) -> 0 | D40: =SUMIF(ALIF_Y2015!I:I,A40,ALIF_Y2015!F:F) -> 0 | E40: =SUMIF(ALIF_Y2016!I:I,A40,ALIF_Y2016!F:F) -> 0 | F40: =SUMIF(ALIF_Y2017!I:I,A40,ALIF_Y2017!F:F) -> 0 | G40: =SUMIF(ALIF_Y2018!I:I,A40,ALIF_Y2018!F:F) -> 0 | H40: =SUMIF(ALIF_Y2019!I:I,A40,ALIF_Y2019!F:F) -> 0 | I40: =SUMIF(ALIF_Y2020!I:I,A40,ALIF_Y2020!F:F) -> 0 | J40: =SUMIF(ALIF_Y2021!I:I,A40,ALIF_Y2021!F:F) -> 0 | K40: =SUMIF(ALIF_Y2022!I:I,A40,ALIF_Y2022!F:F) -> 0 | L40: =SUMIF(ALIF_Y2023!I:I,A40,ALIF_Y2023!F:F) -> 0 | M40: =SUMIF(ALIF_Y2024!I:I,A40,ALIF_Y2024!F:F) -> 24243.5 | N40: =SUMIF(ALIF_Y2025!I:I,A40,ALIF_Y2025!F:F) -> 147339.16
A41: Back office Support | C41: =SUMIF(ALIF_Y2014!I:I,A41,ALIF_Y2014!F:F) -> 17234.6 | D41: =SUMIF(ALIF_Y2015!I:I,A41,ALIF_Y2015!F:F) -> 5201 | E41: =SUMIF(ALIF_Y2016!I:I,A41,ALIF_Y2016!F:F) -> 52054 | F41: =SUMIF(ALIF_Y2017!I:I,A41,ALIF_Y2017!F:F) -> 40763.3 | G41: =SUMIF(ALIF_Y2018!I:I,A41,ALIF_Y2018!F:F) -> 100440.99 | H41: =SUMIF(ALIF_Y2019!I:I,A41,ALIF_Y2019!F:F) -> -488046.26 | I41: =SUMIF(ALIF_Y2020!I:I,A41,ALIF_Y2020!F:F) -> 2025126.3 | J41: =SUMIF(ALIF_Y2021!I:I,A41,ALIF_Y2021!F:F) -> 183980.26 | K41: =SUMIF(ALIF_Y2022!I:I,A41,ALIF_Y2022!F:F) -> 170065.17 | L41: =SUMIF(ALIF_Y2023!I:I,A41,ALIF_Y2023!F:F) -> 8953.96 | M41: =SUMIF(ALIF_Y2024!I:I,A41,ALIF_Y2024!F:F) -> 41863.288 | N41: =SUMIF(ALIF_Y2025!I:I,A41,ALIF_Y2025!F:F) -> 58776.647
A42: AIMS expenses | C42: =SUMIF(ALIF_Y2014!I:I,A42,ALIF_Y2014!F:F) -> 0 | D42: =SUMIF(ALIF_Y2015!I:I,A42,ALIF_Y2015!F:F) -> 0 | E42: =SUMIF(ALIF_Y2016!I:I,A42,ALIF_Y2016!F:F) -> 0 | F42: =SUMIF(ALIF_Y2017!I:I,A42,ALIF_Y2017!F:F) -> 0 | G42: =SUMIF(ALIF_Y2018!I:I,A42,ALIF_Y2018!F:F) -> 0 | H42: =SUMIF(ALIF_Y2019!I:I,A42,ALIF_Y2019!F:F) -> 0 | I42: =SUMIF(ALIF_Y2020!I:I,A42,ALIF_Y2020!F:F) -> 0 | J42: =SUMIF(ALIF_Y2021!I:I,A42,ALIF_Y2021!F:F) -> 0 | K42: =SUMIF(ALIF_Y2022!I:I,A42,ALIF_Y2022!F:F) -> 700886 | L42: =SUMIF(ALIF_Y2023!I:I,A42,ALIF_Y2023!F:F) -> 0 | M42: =SUMIF(ALIF_Y2024!I:I,A42,ALIF_Y2024!F:F) -> 0 | N42: =SUMIF(ALIF_Y2025!I:I,A42,ALIF_Y2025!F:F) -> 0
A44: General and Admin | C44: =SUM(C34:C43) -> 7702424.1 | D44: =SUM(D34:D43) -> 7094796.7 | E44: =SUM(E34:E43) -> 7350629.3 | F44: =SUM(F34:F43) -> 9356300.1 | G44: =SUM(G34:G43) -> 9930132.1 | H44: =SUM(H34:H43) -> 10394149 | I44: =SUM(I34:I43) -> 16562492 | J44: =SUM(J34:J43) -> 13964301 | ... N44: =SUM(N34:N43) -> 26917588
A46: Bad debts expense | C46: =SUMIF(ALIF_Y2014!I:I,A46,ALIF_Y2014!F:F) -> 700005.97 | D46: =SUMIF(ALIF_Y2015!I:I,A46,ALIF_Y2015!F:F) -> 133917.82 | E46: =SUMIF(ALIF_Y2016!I:I,A46,ALIF_Y2016!F:F) -> 0 | F46: =SUMIF(ALIF_Y2017!I:I,A46,ALIF_Y2017!F:F) -> 0 | G46: =SUMIF(ALIF_Y2018!I:I,A46,ALIF_Y2018!F:F) -> 0 | H46: =SUMIF(ALIF_Y2019!I:I,A46,ALIF_Y2019!F:F) -> 0 | I46: =SUMIF(ALIF_Y2020!I:I,A46,ALIF_Y2020!F:F) -> 325461 | J46: =SUMIF(ALIF_Y2021!I:I,A46,ALIF_Y2021!F:F) -> 248775 | K46: =SUMIF(ALIF_Y2022!I:I,A46,ALIF_Y2022!F:F) -> 103333.33 | L46: =SUMIF(ALIF_Y2023!I:I,A46,ALIF_Y2023!F:F) -> 8931099.4 | M46: =SUMIF(ALIF_Y2024!I:I,A46,ALIF_Y2024!F:F) -> -5119898.6 | N46: =SUMIF(ALIF_Y2025!I:I,A46,ALIF_Y2025!F:F) -> -678521.16
A47: Inventory Adjustment Expense | C47: =SUMIF(ALIF_Y2014!I:I,A47,ALIF_Y2014!F:F) -> 0 | D47: =SUMIF(ALIF_Y2015!I:I,A47,ALIF_Y2015!F:F) -> 0 | E47: =SUMIF(ALIF_Y2016!I:I,A47,ALIF_Y2016!F:F) -> 0 | F47: =SUMIF(ALIF_Y2017!I:I,A47,ALIF_Y2017!F:F) -> 0 | G47: =SUMIF(ALIF_Y2018!I:I,A47,ALIF_Y2018!F:F) -> 0 | H47: =SUMIF(ALIF_Y2019!I:I,A47,ALIF_Y2019!F:F) -> 0 | I47: =SUMIF(ALIF_Y2020!I:I,A47,ALIF_Y2020!F:F) -> 0 | J47: =SUMIF(ALIF_Y2021!I:I,A47,ALIF_Y2021!F:F) -> 0 | K47: =SUMIF(ALIF_Y2022!I:I,A47,ALIF_Y2022!F:F) -> 0 | L47: =SUMIF(ALIF_Y2023!I:I,A47,ALIF_Y2023!F:F) -> 0 | M47: =SUMIF(ALIF_Y2024!I:I,A47,ALIF_Y2024!F:F) -> 3148512.3 | N47: =SUMIF(ALIF_Y2025!I:I,A47,ALIF_Y2025!F:F) -> 0
A49: OPERATING INCOME (EBITDA) | C49: =C24-C32-C44-C46-C47 -> 18580847 | D49: =D24-D32-D44-D46-D47 -> 15090112 | E49: =E24-E32-E44-E46-E47 -> 7150161.8 | F49: =F24-F32-F44-F46-F47 -> 4111239.8 | G49: =G24-G32-G44-G46-G47 -> 8129965.8 | H49: =H24-H32-H44-H46-H47 -> 10782838 | I49: =I24-I32-I44-I46-I47 -> -13774255 | J49: =J24-J32-J44-J46-J47 -> 9389608.7 | ... N49: =N24-N32-N44-N46-N47 -> -29788746
A51: Finance cost | C51: =SUMIF(ALIF_Y2014!I:I,A51,ALIF_Y2014!F:F) -> 1986535.1 | D51: =SUMIF(ALIF_Y2015!I:I,A51,ALIF_Y2015!F:F) -> 1159554.7 | E51: =SUMIF(ALIF_Y2016!I:I,A51,ALIF_Y2016!F:F) -> 1539704.4 | F51: =SUMIF(ALIF_Y2017!I:I,A51,ALIF_Y2017!F:F) -> 1568335 | G51: =SUMIF(ALIF_Y2018!I:I,A51,ALIF_Y2018!F:F) -> 2338864.7 | H51: =SUMIF(ALIF_Y2019!I:I,A51,ALIF_Y2019!F:F) -> 3369252 | I51: =SUMIF(ALIF_Y2020!I:I,A51,ALIF_Y2020!F:F) -> 3139563.6 | J51: =SUMIF(ALIF_Y2021!I:I,A51,ALIF_Y2021!F:F) -> 4025597.3 | K51: =SUMIF(ALIF_Y2022!I:I,A51,ALIF_Y2022!F:F) -> 4641310.1 | L51: =SUMIF(ALIF_Y2023!I:I,A51,ALIF_Y2023!F:F) -> 5894124.6 | M51: =SUMIF(ALIF_Y2024!I:I,A51,ALIF_Y2024!F:F) -> 7716907.1 | N51: =SUMIF(ALIF_Y2025!I:I,A51,ALIF_Y2025!F:F) -> 11618933
...

Sheet P&L
A1: ALIF
A2: Profit & Loss
A3: =BS!A3 -> 31 December 2025
C4: MAY 2025 | G4: MAY 2024 | K4: MAY 2023 | O4: MAY 2022 | S4: YTD MAY 2025 | W4: YTD MAY 2024 | AA4: YTD MAY 2023 | AE4: YTD MAY 2022
C5: Consolidated | D5: ALIF | E5: Vision | G5: Consolidated | H5: ALIF | I5: Vision | K5: Consolidated | L5: ALIF | M5: Vision | O5: Consolidated | P5: ALIF | Q5: Vision | S5: Consolidated | T5: ALIF | U5: Vision | W5: Consolidated | X5: ALIF | Y5: Vision | AA5: Consolidated | AB5: ALIF | AC5: Vision | AE5: Consolidated | AF5: ALIF | AG5: Vision
A6: Sales | C6: =SUM(D6:E6) -> #REF! | D6: =-SUMIF(#REF!,A6,#REF!) -> #REF! | E6: =-SUMIF(#REF!,A6,#REF!) -> #REF! | G6: =SUM(H6:I6) -> #REF! | H6: =-SUMIF(ALIF_Y2016!I:I,A6,ALIF_Y2016!F:F)-D6 -> #REF! | I6: =-SUMIF(#REF!,A6,#REF!)-E6 -> #REF! | K6: =SUM(L6:M6) -> #REF! | L6: =D6+H6 -> #REF! | M6: =E6+I6 -> #REF! | O6: =SUM(P6:Q6) -> #REF! | P6: =-SUMIF(#REF!,A6,#REF!) -> #REF! | Q6: =-SUMIF(#REF!,A6,#REF!) -> #REF! | S6: =SUM(T6:U6) -> #REF! | T6: =-SUMIF(#REF!,Q6,#REF!) -> #REF! | U6: =-SUMIF(#REF!,Q6,#REF!) -> #REF! | W6: =SUM(X6:Y6) -> #REF! | X6: =-SUMIF(ALIF_Y2016!Y:Y,Q6,ALIF_Y2016!V:V)-T6 -> #REF! | Y6: =-SUMIF(#REF!,Q6,#REF!)-U6 -> #REF! | AA6: =SUM(AB6:AC6) -> #REF! | AB6: =T6+X6 -> #REF! | AC6: =U6+Y6 -> #REF! | AE6: =SUM(AF6:AG6) -> #REF! | AF6: =-SUMIF(#REF!,Q6,#REF!) -> #REF! | AG6: =-SUMIF(#REF!,Q6,#REF!) -> #REF!
