Workbook

Sheet README
A1: ALIF GROUP — AUTOMATED IFRS FINANCIAL STATEMENT & HISTORICAL ANALYSIS WORKBOOK
A2: Alif standalone · VH standalone · Consolidated — nine months ended 30 September 2026 | Engine v1.2, final 17-Oct-2026 (COGS indirect salaries audit + client side-by-side)
A4: HOW THIS WORKBOOK WORKS (plug-and-play)
A5: 1. Paste every numeric September YTD GL row from FS report 202609 IFRS.xlsx into TB_Input_Alif / TB_Input_VH (A–F, row 3 onward), including repeated IDs and manual journal rows; G–J classify via Map.
A6: 2. IS_/BS_/CF_ statements recalculate from raw TB inputs and Map; dynamic SUMIFS aggregate all rows for each account/statement line.
A7: 3. New GL IDs show ⚠ UNMAPPED in G–J and Checks section 2; add the ID to Map. The Sep-26 refresh now has zero unmapped rows.
A8: 4. The historical sheets (YearlyAlif, BS, P&L_2014-2025, Charts_BS, Charts_P&L) carry a new "Sep-26 YTD" column fed by TB_Input_Alif; all trend charts now run Y2014 → Sep-26 YTD. Charts_YTD adds the entity dashboard.
A10: SHEET MAP
A11: README · Checks — control panel: TB integrity, mapping coverage, BS equilibrium, cross-statement ties, consolidation info · FS_SideBySide_Comparison — client vs engine IS/BS/CFS comparison with justifications · Problem_Areas_&_Solutions — management analysis
A12: IS_/BS_/CF_Consol — consolidated IFRS statements with Alif | VH | Eliminations | Consolidated columns
A13: IS_/BS_/CF_Alif, IS_/BS_/CF_VH — standalone IFRS statements (BS includes 1-Jan-26 opening column)
A14: 14. TB_Input_Alif / TB_Input_VH — raw September YTD rows from FS report 202609 IFRS.xlsx (source fields A–F: GL ID, description, OB, debit, credit, CB; repeated account IDs are retained).
... A46: • Retained earnings now include unclosed opening P&L per TB, so the BS difference is 0.00 SAR for Alif, VH and Consolidated. Checks section 7 ties net result, total assets, equity and cash to the client file.

Sheet Checks
A1: CONTROL & INTEGRITY CHECKS
A2: All checks recalculate automatically. PASS requires the difference column to be ±0.01.
A4: Check | B4: Alif | C4: VH | D4: Consolidated | E4: Status | F4: How computed / what to do on failure
A5: 1. Trial balance integrity
A6: Σ of closing balances (CB) = 0 | B6: =SUM(TB_Input_Alif!$F:$F) -> -4.5634806e-08 | C6: =SUM(TB_Input_VH!$F:$F) -> -3.8417056e-09 | D6: =B6+C6 -> -4.9476512e-08 | E6: =IF(AND(ABS(B6)<0.01,ABS(C6)<0.01,ABS(D6)<0.01),"PASS","REVIEW") -> PASS | F6: Raw debit–credit equality of the pasted TB (txtFiscalPerCB). If not nil, the TB export itself is out of balance.
A7: Σ of opening balances (OB) = 0 | B7: =SUM(TB_Input_Alif!$C:$C) -> -4.4703484e-08 | C7: =SUM(TB_Input_VH!$C:$C) -> 1.6880222e-09 | D7: =B7+C7 -> -4.3015461e-08 | E7: =IF(AND(ABS(B7)<0.01,ABS(C7)<0.01,ABS(D7)<0.01),"PASS","REVIEW") -> PASS | F7: Raw debit–credit equality of opening balances (txtFiscalPerOB).
A8: Σ(CB) − Σ(OB) − Σ(Dr − Cr) = 0 | B8: =SUM(TB_Input_Alif!$F:$F)-SUM(TB_Input_Alif!$C:$C)-(SUM(TB_Input_Alif!$D:$D)-SUM(TB_Input_Alif!$E:$E)) -> 2.3832545e-06 | C8: =SUM(TB_Input_VH!$F:$F)-SUM(TB_Input_VH!$C:$C)-(SUM(TB_Input_VH!$D:$D)-SUM(TB_Input_VH!$E:$E)) -> -4.8236689e-07 | D8: =B8+C8 -> 1.9008876e-06 | E8: =IF(AND(ABS(B8)<0.01,ABS(C8)<0.01,ABS(D8)<0.01),"PASS","REVIEW") -> PASS | F8: Movement arithmetic of the TB export (CB = OB + Dr − Cr).
A9: 2. Mapping coverage (Map = single source of truth)
A10: Rows in TB with NO Map classification | B10: =COUNTIFS(TB_Input_Alif!$G:$G,"⚠ UNMAPPED") -> 0 | C10: =COUNTIFS(TB_Input_VH!$G:$G,"⚠ UNMAPPED") -> 0 | D10: =B10+C10 -> 0 | E10: =IF(AND(ABS(B10)<0.01,ABS(C10)<0.01,ABS(D10)<0.01),"PASS","REVIEW") -> PASS | F10: Must be 0. If > 0: add the GL account to the Map sheet (columns A–F); statements include it automatically.
A11: Σ of balances on unmapped rows | B11: =SUMIFS(TB_Input_Alif!$F:$F,TB_Input_Alif!$G:$G,"⚠ UNMAPPED") -> 0 | C11: =SUMIFS(TB_Input_VH!$F:$F,TB_Input_VH!$G:$G,"⚠ UNMAPPED") -> 0 | D11: =B11+C11 -> 0 | E11: =IF(AND(ABS(B11)<0.01,ABS(C11)<0.01,ABS(D11)<0.01),"PASS","REVIEW") -> PASS | F11: Value leaking out of the statements while unmapped rows exist.
A12: 3. Balance sheet equilibrium (Total assets = Total equity + liabilities)
A13: Total assets | B13: =BS_Alif!C21 -> 2.8792338e+08 | C13: =BS_VH!C21 -> 70047559 | D13: =BS_Consol!F21 -> 3.5797094e+08 | F13: Per statement of financial position.
A14: Total equity and liabilities | B14: =BS_Alif!C47 -> 2.8792338e+08 | C14: =BS_VH!C47 -> 70047559 | D14: =BS_Consol!F48 -> 3.5797094e+08 | F14: Per statement of financial position.
A15: Difference (assets − equity&liabilities) | B15: =B13-B14 -> 0 | C15: =C13-C14 -> 0 | D15: =D13-D14 -> 0 | E15: =IF(AND(ABS(B15)<0.01,ABS(C15)<0.01,ABS(D15)<0.01),"PASS","REVIEW") -> PASS | F15: Must be 0.00 SAR for Alif, VH and Consolidated; no balance-sheet plug is used.
A16: Unclosed opening P&L per TB (Σ IS opening balances) — now carried in retained earnings | B16: =-SUMIFS(TB_Input_Alif!$C:$C,TB_Input_Alif!$G:$G,"IS") -> 0 | C16: =-SUMIFS(TB_Input_VH!$C:$C,TB_Input_VH!$G:$G,"IS") -> 0.004 | D16: =B16+C16 -> 0.004 | F16: Informational. Since 17-Oct-2026 BS_Alif/BS_VH retained earnings include this TB residual (VH SAR 0.004 rounding), so the BS balances exactly with no plug.
A17: Unexplained difference (Difference − Expected residual) | B17: =B15 -> 0 | C17: =C15 -> 0 | D17: =D15 -> 0 | E17: =IF(AND(ABS(B17)<0.01,ABS(C17)<0.01,ABS(D17)<0.01),"PASS","REVIEW") -> PASS | F17: MUST BE NIL (±0.01 SAR). Equals the row-15 difference because the opening P&L residual is now included in retained earnings. Any residual means unmapped or misclassified GLs.
A18: 4. Cross-statement ties
A19: TCI per IS = −Σ(IS TB movement) | B19: =IS_Alif!C65-(-SUMIFS(TB_Input_Alif!$F:$F,TB_Input_Alif!$G:$G,"IS")+SUMIFS(TB_Input_Alif!$C:$C,TB_Input_Alif!$G:$G,"IS")) -> 0 | C19: =IS_VH!C65-(-SUMIFS(TB_Input_VH!$F:$F,TB_Input_VH!$G:$G,"IS")+SUMIFS(TB_Input_VH!$C:$C,TB_Input_VH!$G:$G,"IS")) -> -2.0954758e-09 | D19: =IS_Consol!F65-((-SUMIFS(TB_Input_Alif!$F:$F,TB_Input_Alif!$G:$G,"IS")+SUMIFS(TB_Input_Alif!$C:$C,TB_Input_Alif!$G:$G,"IS"))+(-SUMIFS(TB_Input_VH!$F:$F,TB_Input_VH!$G:$G,"IS")+SUMIFS(TB_Input_VH!$C:$C,TB_Input_VH!$G:$G,"IS"))-SUM(IS_Consol!$H$69:$H$71)) -> 0 | E19: =IF(AND(ABS(B19)<0.01,ABS(C19)<0.01,ABS(D19)<0.01),"PASS","REVIEW") -> PASS | F19: Every IS-mapped account must flow into total comprehensive income — nil means full coverage.
A20: Closing cash per CF − cash per BS | B20: =CF_Alif!C43-BS_Alif!C18 -> 0 | C20: =CF_VH!C43-BS_VH!C18 -> 1.2572855e-08 | D20: =CF_Consol!F43-BS_Consol!F18 -> 0 | E20: =IF(AND(ABS(B20)<0.01,ABS(C20)<0.01,ABS(D20)<0.01),"PASS","REVIEW") -> PASS | F20: Cash flow statement ties to the balance sheet by construction (every Map BS line is enumerated).
A22: 5. Consolidation information
A23: Intercompany balances eliminated (BS) — net amount | D23: =SUM(BS_Consol!$H$53:$H$55) -> 19243.861 | F23: Alif a/c 270005 due to VH (SAR 1,625,866.01) less VH a/c 330004 due from Alif (SAR 1,606,622.15) = net elimination in Due to RP.
A24: Unreconciled IC difference in consolidated equity | D24: =BS_Consol!F30 -> 19243.861 | F24: Disclosed as its own equity line — investigate/clear before year-end audit.
A25: Intercompany P&L eliminated (manual input) | D25: =SUM(IS_Consol!$H$69:$H$71) -> 0 | F25: Enter on IS_Consol elimination table when IC trading exists (none identified in Sep-26 TBs).
A27: 6. Factory indirect salaries — COGS classification (Step 1 audit, 17-Oct-2026)
A28: Map: target factory-labour GLs (600001/600035/600041/600044) NOT mapped to IS · Cost of sales · Overhead - Labor Cost | B28: =4-SUMPRODUCT(COUNTIFS(Map!$A$2:$A$400,{600001,600035,600041,600044},Map!$C$2:$C$400,"IS",Map!$D$2:$D$400,"Cost of sales",Map!$E$2:$E$400,"Overhead - Labor Cost")) -> 0 | C28: =B28 -> 0 | D28: =B28 -> 0 | E28: =IF(AND(ABS(B28)<0.01,ABS(C28)<0.01,ABS(D28)<0.01),"PASS","REVIEW") -> PASS | F28: Must be 0. Map is shared by both entities, so the same value shows in all columns. Verifies FS Group = IS, SubGroup = Cost of sales, FS Line = Overhead - Labor Cost (Indirect Salaries).
A29: TB rows of 600001/600035/600041/600044 not classified to COGS Overhead - Labor Cost | B29: =SUMPRODUCT(ISNUMBER(MATCH(TB_Input_Alif!$A$3:$A$1000,{600001,600035,600041,600044},0))*(((TB_Input_Alif!$G$3:$G$1000<>"IS")+(TB_Input_Alif!$H$3:$H$1000<>"Cost of sales")+(TB_Input_Alif!$I$3:$I$1000<>"Overhead - Labor Cost"))>0)) -> 0 | C29: =SUMPRODUCT(ISNUMBER(MATCH(TB_Input_VH!$A$3:$A$1000,{600001,600035,600041,600044},0))*(((TB_Input_VH!$G$3:$G$1000<>"IS")+(TB_Input_VH!$H$3:$H$1000<>"Cost of sales")+(TB_Input_VH!$I$3:$I$1000<>"Overhead - Labor Cost"))>0)) -> 0 | D29: =B29+C29 -> 0 | E29: =IF(AND(ABS(B29)<0.01,ABS(C29)<0.01,ABS(D29)<0.01),"PASS","REVIEW") -> PASS | F29: Row-level test on the pasted TB (columns G-I). Must be 0.
A30: Factory (6000xx) GL rows presented in G&A "Salaries and wages" | B30: =COUNTIFS(TB_Input_Alif!$A:$A,">=600000",TB_Input_Alif!$A:$A,"<=600099",TB_Input_Alif!$I:$I,"Salaries and wages") -> 0 | C30: =COUNTIFS(TB_Input_VH!$A:$A,">=600000",TB_Input_VH!$A:$A,"<=600099",TB_Input_VH!$I:$I,"Salaries and wages") -> 0 | D30: =B30+C30 -> 0 | E30: =IF(AND(ABS(B30)<0.01,ABS(C30)<0.01,ABS(D30)<0.01),"PASS","REVIEW") -> PASS | F30: Must be 0. Factory payroll must not be presented below gross profit.
A31: Admin salaries 700001 rows NOT in General & Administrative | B31: =COUNTIFS(TB_Input_Alif!$A:$A,700001,TB_Input_Alif!$H:$H,"<>General and Admin") -> 0 | C31: =COUNTIFS(TB_Input_VH!$A:$A,700001,TB_Input_VH!$H:$H,"<>General and Admin") -> 0 | D31: =B31+C31 -> 0 | E31: =IF(AND(ABS(B31)<0.01,ABS(C31)<0.01,ABS(D31)<0.01),"PASS","REVIEW") -> PASS | F31: Must be 0. Administrative salaries (700001) stay in G&A below gross profit / above operating profit.
A32: IS "Overhead - Labor Cost" − Σ TB movement of all COGS Overhead - Labor Cost GLs | B32: =IS_Alif!C16-(SUMIFS(TB_Input_Alif!$F:$F,TB_Input_Alif!$H:$H,"Cost of sales",TB_Input_Alif!$I:$I,"Overhead - Labor Cost")-SUMIFS(TB_Input_Alif!$C:$C,TB_Input_Alif!$H:$H,"Cost of sales",TB_Input_Alif!$I:$I,"Overhead - Labor Cost")) -> 0 | C32: =IS_VH!C16-(SUMIFS(TB_Input_VH!$F:$F,TB_Input_VH!$H:$H,"Cost of sales",TB_Input_VH!$I:$I,"Overhead - Labor Cost")-SUMIFS(TB_Input_VH!$C:$C,TB_Input_VH!$H:$H,"Cost of sales",TB_Input_VH!$I:$I,"Overhead - Labor Cost")) -> 0 | D32: =IS_Consol!F16-IS_Consol!C16-IS_Consol!D16+B32+C32 -> -2.3283064e-10 | E32: =IF(AND(ABS(B32)<0.01,ABS(C32)<0.01,ABS(D32)<0.01),"PASS","REVIEW") -> PASS | F32: Indirect salaries flow fully into COGS (above gross profit); the consolidated column also tests IS_Consol linkage.
A33: Factory indirect salaries in COGS (SAR, informational) | B33: =IS_Alif!C16 -> 5969397 | C33: =IS_VH!C16 -> 1078114.3 | D33: =IS_Consol!F16 -> 7047511.3 | E33: INFO | F33: Overhead - Labor Cost line on IS_Alif / IS_VH / IS_Consol (row 16, inside Total cost of sales, row 21).
A34: Administrative salaries & wages in G&A (SAR, informational) | B34: =IS_Alif!C35 -> 11195522 | C34: =IS_VH!C35 -> 1546060.7 | D34: =IS_Consol!F35 -> 12741583 | E34: INFO | F34: G&A Salaries and wages line (row 35, below gross profit, above operating income).
A36: 7. Tie-out to client reference file (FS report 202609 IFRS) — see FS_SideBySide_Comparison
A37: Net profit / (loss): master − client | B37: =FS_SideBySide_Comparison!D54 -> 2.5331974e-07 | C37: =FS_SideBySide_Comparison!D88 -> -0.0040000023 | D37: =FS_SideBySide_Comparison!D122 -> -0.0039997101 | E37: =IF(AND(ABS(B37)<0.01,ABS(C37)<0.01,ABS(D37)<0.01),"PASS","REVIEW") -> PASS | F37: Must be nil. All IS presentation differences are inside operating costs and net to zero.
A38: Total assets: master − client | B38: =FS_SideBySide_Comparison!D141 -> 0 | C38: =FS_SideBySide_Comparison!D176 -> 0 | D38: =FS_SideBySide_Comparison!D211 -> 0 | E38: =IF(AND(ABS(B38)<0.01,ABS(C38)<0.01,ABS(D38)<0.01),"PASS","REVIEW") -> PASS | F38: Must be nil.
A39: Total equity: master − client (consolidated = IC difference) | B39: =FS_SideBySide_Comparison!D147 -> 2.4586916e-07 | C39: =FS_SideBySide_Comparison!D182 -> 0 | D39: =FS_SideBySide_Comparison!D218-BS_Consol!F30 -> 2.3609027e-07 | E39: =IF(AND(ABS(B39)<0.01,ABS(C39)<0.01,ABS(D39)<0.01),"PASS","REVIEW") -> PASS | F39: Consolidated column excludes the disclosed IC consolidation difference (BS_Consol!F30, SAR 19,243.86).
A40: Closing cash: master − client (client rounding tolerance ±1.00) | B40: =FS_SideBySide_Comparison!D267 -> 0.46 | C40: =FS_SideBySide_Comparison!D300 -> 0.24500001 | D40: =FS_SideBySide_Comparison!D333 -> 0.70499999 | E40: =IF(AND(ABS(B40)<1,ABS(C40)<1,ABS(D40)<1),"PASS","REVIEW") -> PASS | F40: The client CF carries rounding check differences (0.46 / 0.25 / 0.71). The master closing cash ties exactly to its BS (Checks row 20).
A42: Legend: blue cells = user input · black = formula · ⚠ UNMAPPED = extend the Map sheet. No statement line contains a hardcoded adjustment.
A43: Updated 17-Oct-2026: sections 6-7 added (COGS indirect salaries audit; client tie-out). Unclosed opening P&L is now carried in retained earnings, so the BS difference is 0.00 for all entities.

Sheet TB_Comparison_Justification
A1: TB COMPARISON & JUSTIFICATION — SEPTEMBER 2026
A2: Old = original master before refresh · Revised = FS report 202609 IFRS.xlsx YTD to 30-Sep-2026 · SAR
A4: Account Head | B4: Entity | C4: Old Balance (SAR) | D4: Revised Balance (SAR) | E4: Difference (SAR) | F4: Justification / Remarks
A5: Sales Revenue | B5: Alif | C5: 5810727.4 | D5: =IS_Alif!C6 -> 1.2646792e+08 | E5: =D5-C5 -> 1.206572e+08 | F5: The prior model omitted multi-line credits for SALES REVENUE (410001); all September YTD postings, duplicate IDs and manual sales entries are now aggregated. Alif ties to SAR 126.47m.
A6: Sales Revenue | B6: VH | C6: 44443752 | D6: =IS_VH!C6 -> 44443752 | E6: =D6-C6 -> 0 | F6: The prior model omitted multi-line credits for SALES REVENUE (410001); all September YTD postings, duplicate IDs and manual sales entries are now aggregated. Alif ties to SAR 126.47m.
A7: Sales Revenue | B7: Consolidated | C7: 50254479 | D7: =IS_Consol!F6 -> 1.7091168e+08 | E7: =D7-C7 -> 1.206572e+08 | F7: The prior model omitted multi-line credits for SALES REVENUE (410001); all September YTD postings, duplicate IDs and manual sales entries are now aggregated. Alif ties to SAR 126.47m.
A8: Cost of sales / raw materials | B8: Alif | C8: 8134754.9 | D8: =IS_Alif!C21 -> 1.3371511e+08 | E8: =D8-C8 -> 1.2558036e+08 | F8: Revised total cost of sales; raw materials remain included. The three specified outbound freight accounts are excluded from COGS after IFRS reclassification.
A9: Cost of sales / raw materials | B9: VH | C9: 44841164 | D9: =IS_VH!C21 -> 41950416 | E9: =D9-C9 -> -2890748.4 | F9: Revised total cost of sales; raw materials remain included. The three specified outbound freight accounts are excluded from COGS after IFRS reclassification.
A10: Cost of sales / raw materials | B10: Consolidated | C10: 52975919 | D10: =IS_Consol!F21 -> 1.7566553e+08 | E10: =D10-C10 -> 1.2268961e+08 | F10: Revised total cost of sales; raw materials remain included. The three specified outbound freight accounts are excluded from COGS after IFRS reclassification.
A11: Freight & Shipping Expenses (S&D) | B11: Alif | C11: 697684.72 | D11: =IS_Alif!C31 -> 9397187 | E11: =D11-C11 -> 8699502.3 | F11: Old balance is the specified GL accounts' old YTD movement (then presented in COGS); revised balance is presented below gross profit in Selling & Distribution.
A12: Freight & Shipping Expenses (S&D) | B12: VH | C12: 190520 | D12: =IS_VH!C31 -> 190520 | E12: =D12-C12 -> 0 | F12: Old balance is the specified GL accounts' old YTD movement (then presented in COGS); revised balance is presented below gross profit in Selling & Distribution.
A13: Freight & Shipping Expenses (S&D) | B13: Consolidated | C13: 888204.72 | D13: =IS_Consol!F31 -> 9587707 | E13: =D13-C13 -> 8699502.3 | F13: Old balance is the specified GL accounts' old YTD movement (then presented in COGS); revised balance is presented below gross profit in Selling & Distribution.
A14: General & Administrative Expenses | B14: Alif | C14: 983533.27 | D14: =IS_Alif!C44 -> 13317437 | E14: =D14-C14 -> 12333903 | F14: Map-driven G&A total. Account 800001 is classified to G&A salaries and wages in the September IFRS report; 700080 is mapped to Back office Support.
A15: General & Administrative Expenses | B15: VH | C15: 1695982.5 | D15: =IS_VH!C44 -> 1695982.5 | E15: =D15-C15 -> 0 | F15: Map-driven G&A total. Account 800001 is classified to G&A salaries and wages in the September IFRS report; 700080 is mapped to Back office Support.
A16: General & Administrative Expenses | B16: Consolidated | C16: 2679515.7 | D16: =IS_Consol!F44 -> 15013419 | E16: =D16-C16 -> 12333903 | F16: Map-driven G&A total. Account 800001 is classified to G&A salaries and wages in the September IFRS report; 700080 is mapped to Back office Support.
A17: Net Income | B17: Alif | C17: -4097617.8 | D17: =IS_Alif!C60 -> -40498413 | E17: =D17-C17 -> -36400795 | F17: Recomputed from refreshed YTD movements and all mapped GL rows. Freight reclassification is presentation-only; account 800001 follows the source IFRS classification.
A18: Net Income | B18: VH | C18: -3118011.4 | D18: =IS_VH!C60 -> -1356565.7 | E18: =D18-C18 -> 1761445.7 | F18: Recomputed from refreshed YTD movements and all mapped GL rows. Freight reclassification is presentation-only; account 800001 follows the source IFRS classification.
A19: Net Income | B19: Consolidated | C19: -7215629.2 | D19: =IS_Consol!F60 -> -41854979 | E19: =D19-C19 -> -34639349 | F19: Recomputed from refreshed YTD movements and all mapped GL rows. Freight reclassification is presentation-only; account 800001 follows the source IFRS classification.
A21: CONTROL TIE-OUTS & DATA COMPLETENESS
A22: Control | B22: Calculated | C22: Source / Expected | D22: Expected Value | E22: Variance | F22: Status
A23: Alif numeric GL rows imported | B23: =COUNTA(TB_Input_Alif!$A:$A)-2 -> 431 | C23: ALIF_YtdSep numeric IDs | D23: 431 | E23: =B23-D23 -> 0 | F23: =IF(ABS(E23)<0.01,"PASS","REVIEW") -> PASS
A24: VH numeric GL rows imported | B24: =COUNTA(TB_Input_VH!$A:$A)-2 -> 265 | C24: VH_YtdSep numeric IDs | D24: 265 | E24: =B24-D24 -> 0 | F24: =IF(ABS(E24)<0.01,"PASS","REVIEW") -> PASS
A25: Alif YTD sales | B25: =IS_Alif!C6 -> 1.2646792e+08 | C25: P&L_2026(Mo)!AY8 | D25: 1.2646792e+08 | E25: =B25-D25 -> 0 | F25: =IF(ABS(E25)<0.01,"PASS","REVIEW") -> PASS
A26: Consolidated YTD sales | B26: =IS_Consol!F6 -> 1.7091168e+08 | C26: P&L_2026(Mo)!AX8 | D26: 1.7091168e+08 | E26: =B26-D26 -> 0 | F26: =IF(ABS(E26)<0.01,"PASS","REVIEW") -> PASS
A27: Unmapped GL rows | B27: =Checks!D10 -> 0 | C27: Required | D27: 0 | E27: =B27-D27 -> 0 | F27: =IF(ABS(E27)<0.01,"PASS","REVIEW") -> PASS
A28: Alif balance-sheet difference | B28: =Checks!B15 -> 0 | C28: Required (±0.01 SAR) | D28: 0 | E28: =B28-D28 -> 0 | F28: =IF(ABS(E28)<0.01,"PASS","REVIEW") -> PASS
A29: VH balance-sheet difference | B29: =Checks!C15 -> 0 | C29: Required (±0.01 SAR) | D29: 0 | E29: =B29-D29 -> 0 | F29: =IF(ABS(E29)<0.01,"PASS","REVIEW") -> PASS
A30: Consolidated balance-sheet difference | B30: =Checks!D15 -> 0 | C30: Required (±0.01 SAR) | D30: 0 | E30: =B30-D30 -> 0 | F30: =IF(ABS(E30)<0.01,"PASS","REVIEW") -> PASS
A32: KEY RECTIFICATION NOTES
A33: IFRS freight reclassification: GL accounts 700060, 700067 and 700077 are reclassified from COGS to Selling and Marketing / S&D under IFRS on a separate line below Gross Profit. Account 700047 remains mapped to COGS freight.
A34: Multi-line revenue correction: the prior model omitted multi-line credits for SALES REVENUE (410001). All numeric rows from ALIF_YtdSep / VH_YtdSep are now imported, including repeated 410001 IDs and manual add/remove sales journals; Alif YTD sales are SAR 126,467,923.88.
A35: Consolidated sales tie-out: revised IS_Consol sales equal SAR 170,911,675.61, matching FS report 202609 IFRS.xlsx, P&L_2026(Mo)!AX8 (variance < SAR 0.01).
A36: Mapping completeness: new IDs 520049, 520050 and 700080 were added to Map. 520050 uses the existing Overhead - Labor Cost statement line; account 800001 follows the source IFRS report's G&A classification. No balancing plug is used.
A37: Factory indirect salaries (17-Oct-2026): 600001, 600035, 600041 and 600044 are mapped to COGS "Overhead - Labor Cost" (Indirect Salaries) above gross profit; 600035 was corrected from "Overhead - Rent Labor". Administrative salaries 700001 stay in G&A. Client comparison: see FS_SideBySide_Comparison.

Sheet FS_SideBySide_Comparison
A1: FS SIDE-BY-SIDE COMPARISON — CLIENT REFERENCE vs MASTER ENGINE (IS · BS · CFS)
A2: Nine months ended 30 September 2026 (YTD) · SAR · Client = FS report 202609 IFRS.xlsx (P&L_2026(Mo) cols AX/AY/AZ, BS cols BB/BC/BD, CF cols O/AD/AS — static values, blue) · Master = live formulas linked to IS_/BS_/CF_ sheets of this workbook (black) · Variance = Master − Client.
A3: Sign convention: revenue, income, expenses, assets, liabilities and equity shown positive; profits/(losses) and cash flows signed. Amber variance cells = difference ≥ SAR 0.01, each with an explicit justification. Prepared 17-Oct-2026.
A4: Line Item Header | B4: Reference File (FS report 202609 IFRS) | C4: Master Engine Output (Alif_VH_IFRS_Master_Sep2026_Rectified) | D4: Variance (SAR) | E4: Audit Justification / Remarks
A5: KEY TIE-OUT SUMMARY (links to detailed sections below)
A6: Line Item Header | B6: Reference File (FS report 202609 IFRS) | C6: Master Engine Output (Alif_VH_IFRS_Master_Sep2026_Rectified) | D6: Variance (SAR) | E6: Audit Justification / Remarks
A7: Alif — Net profit / (loss) for the period | B7: =B54 -> -40498413 | C7: =C54 -> -40498413 | D7: =C7-B7 -> 2.5331974e-07 | E7: See Section A1, row 54. Agreed to SAR 0.00, which confirms full mapping coverage.
A8: VH — Net profit / (loss) for the period | B8: =B88 -> -1356565.6 | C8: =C88 -> -1356565.7 | D8: =C8-B8 -> -0.0040000023 | E8: See Section A2, row 88. Agreed to SAR 0.00.
A9: Consolidated — Net profit / (loss) for the period | B9: =B122 -> -41854979 | C9: =C122 -> -41854979 | D9: =C9-B9 -> -0.0039997101 | E9: See Section A3, row 122. Agreed to SAR 0.00.
A10: Alif — Gross profit / (loss) [IFRS freight-out reclass] | B10: =B36 -> -14461403 | C10: =C36 -> -7247188.2 | D10: =C10-B10 -> 7214215.1 | E10: See Section A1, row 36. +7,214,215.08: equal and opposite to the COGS variance.
A11: VH — Gross profit / (loss) [700052 depreciation presentation] | B11: =B70 -> 2078960.3 | C11: =C70 -> 2493336.1 | D11: =C11-B11 -> 414375.81 | E11: See Section A2, row 70. +414,375.81: VH 700052 machine depreciation sits below EBITDA in the master and in COGS in the client file..
A12: Consolidated — Gross profit / (loss) | B12: =B104 -> -12382443 | C12: =C104 -> -4753852.1 | D12: =C12-B12 -> 7628590.9 | E12: See Section A3, row 104. +7,628,590.89 = Alif +7,214,215.08 + VH +414,375.81.
A13: Consolidated — Factory indirect salaries in COGS | B13: =B100 -> 6991304.7 | C13: =C100 -> 7047511.3 | D13: =C13-B13 -> 56206.63 | E13: See Section A3, row 100. +56,206.63 = Alif 600044 (SAR 43,521.63) + VH 600044 (SAR 8,085.00) + VH 600043 (SAR 4,600.00).
A14: Alif — Total assets | B14: =B141 -> 2.8792338e+08 | C14: =C141 -> 2.8792338e+08 | D14: =C14-B14 -> 0 | E14: See Section B1, row 141. Agreed — no variance (ties to client within ±SAR 0.01)..
A15: VH — Total assets | B15: =B176 -> 70047559 | C15: =C176 -> 70047559 | D15: =C15-B15 -> 0 | E15: See Section B2, row 176. Agreed — no variance (ties to client within ±SAR 0.01)..
A16: Consolidated — Total assets | B16: =B211 -> 3.5797094e+08 | C16: =C211 -> 3.5797094e+08 | D16: =C16-B16 -> 0 | E16: See Section B3, row 211. Agreed — no variance (ties to client within ±SAR 0.01).
A17: Consolidated — Total equity [IC elimination SAR 19,243.86] | B17: =B218 -> 23055496 | C17: =C218 -> 23074740 | D17: =C17-B17 -> 19243.861 | E17: See Section B3, row 218. +19,243.86 = consolidation difference on IC balances (the share-capital/RE presentation nets to nil)..
A18: Alif — Closing cash and cash equivalents | B18: =B267 -> 30034455 | C18: =C267 -> 30034455 | D18: =C18-B18 -> 0.46 | E18: See Section C1, row 267. SAR +0.46: the master closing cash ties exactly to the balance sheet (SAR 30,034,455.43); the client CF is SAR 0.46 short of its own BS (client CF row 57)..
A19: VH — Closing cash and cash equivalents | B19: =B300 -> 2763169.9 | C19: =C300 -> 2763170.1 | D19: =C19-B19 -> 0.24500001 | E19: See Section C2, row 300. SAR +0.25: master ties exactly to the BS (SAR 2,763,170.14); client CF check difference..
A20: Consolidated — Closing cash and cash equivalents | B20: =B333 -> 32797625 | C20: =C333 -> 32797626 | D20: =C20-B20 -> 0.70499999 | E20: See Section C3, row 333. SAR +0.71: master ties exactly to the consolidated BS (SAR 32,797,625.57); client CF check difference of 0.71..
A23: SECTION A — INCOME STATEMENT (IS) COMPARISON
A24: A1. Alif (standalone) — Statement of profit or loss · nine months ended 30-Sep-2026 | E24: Master source: IS_Alif (col C) · Client source: P&L_2026(Mo) col AY
A25: Line Item Header | B25: Client Reference File (FS report 202609 IFRS) | C25: Master Engine Output (Alif_VH_IFRS_Master_Sep2026_Rectified) | D25: Variance (SAR) | E25: Audit Justification / Remarks
A26: Sales revenue | B26: 1.2646792e+08 | C26: =IS_Alif!C6 -> 1.2646792e+08 | D26: =C26-B26 -> 0 | E26: Agreed (SAR 126,467,923.88). Multi-line revenue fix: the master sums ALL 18 SALES REVENUE (410001) rows in TB_Input_Alif — multi-line credits, repeated IDs and manual add/remove sales journals — with full-column SUMIFS, plus returns, discounts and scrap (410002-410004). The earlier single-row lookup reported only SAR 5,810,727.40, understating revenue by SAR 120,657,196.48. [Client ref: 'P&L_2026(Mo)'!AY8]
A27: COST OF SALES
A28: Raw materials | B28: 94755694 | C28: =IS_Alif!C9 -> 94755694 | D28: =C28-B28 -> 0 | E28: Agreed. Raw materials (510001, 510003-510005 and the 5200xx material, variance and inventory-adjustment GLs) are classified the same way in both files. [Client ref: 'P&L_2026(Mo)'!AY10]
A29: Direct labour | B29: 15043743 | C29: =IS_Alif!C10 -> 15043743 | D29: =C29-B29 -> 0 | E29: Agreed. Includes 520049 DIRECT EXP - Tickets & Visa (SAR 598.80), a new GL added to Map row 293 on 16-Oct. Before that mapping it showed as ⚠ UNMAPPED. [Client ref: 'P&L_2026(Mo)'!AY11]
A30: Freight expenses (in COGS) | B30: 7753418.6 | C30: =IS_Alif!C11 -> 173224.89 | D30: =C30-B30 -> -7580193.8 | E30: Freight-out reclassification: 700067 FREIGHT-OUT EXPORT (SAR 6,930,832.17) and 700077 Freight Expenses - Drayage (SAR 769,080.27) are moved from COGS to Selling & Distribution under IFRS. Outbound delivery is a selling cost, not part of inventory cost (IAS 2.10 / 2.16(d)). 700060 FREIGHT-OUT EXP. (SAR 1,697,274.54) is S&D in both files. This is partly offset by 700047 DETENTION CHARGES (SAR 119,718.69), which the master keeps in COGS freight and the client shows in G&A 'Govt license and fees'. Net: -7,699,912.44 + 119,718.69 = -7,580,193.75. [Client ref: 'P&L_2026(Mo)'!AY12]
A31: Customs duties and clearances | B31: 2270031.4 | C31: =IS_Alif!C12 -> 2270031.4 | D31: =C31-B31 -> 0 | E31: Agreed. Customs duty and clearance (700070, 700071) are presented in COGS in both files. [Client ref: 'P&L_2026(Mo)'!AY13]
A32: Factory indirect salaries (Overhead - Labor Cost) | B32: 5925875.4 | C32: =IS_Alif!C16+IS_Alif!C19 -> 5969397 | D32: =C32-B32 -> 43521.63 | E32: STEP 1 rectification: +43,521.63 = 600044 Business Trips Exp. - Factory. This is factory supervisory cost, so it is mapped to COGS 'Overhead - Labor Cost' (the client shows it in 'Overhead', also inside COGS). 600001 Indirect Salaries (SAR 5,925,875.39) agrees to the client. That figure already includes 600035 casual labour and 600041 indirect food, which were moved into 600001 by manual JV (net nil on those GLs). The 600035 Map line was corrected from 'Overhead - Rent Labor' to 'Overhead - Labor Cost'; its net YTD balance is nil, so no value changes. [Client ref: 'P&L_2026(Mo)'!AY14]
A33: Depreciation - machines (in COGS) | B33: 6489832.7 | C33: =IS_Alif!C13 -> 6489832.7 | D33: =C33-B33 -> -2.7474016e-07 | E33: Agreed. 600029 M/C & equipment depreciation (SAR 6,489,832.70, booked by manual JV) is in COGS in both files. [Client ref: 'P&L_2026(Mo)'!AY15]
A34: Other factory overhead (consumables, insurance, R&M, rent, utilities) | B34: 8690732.4 | C34: =IS_Alif!C14+IS_Alif!C15+IS_Alif!C17+IS_Alif!C18+IS_Alif!C20 -> 9013189.4 | D34: =C34-B34 -> 322457.04 | E34: +322,457.04, made up of: +328,772.13 700057 WAREHOUSE RENT (master: COGS Overhead - Rent as a storage cost; client: S&D 'Rent'); -43,521.63 600044 moved to Indirect Salaries; +37,206.54 700042 Damaged/expired material & bank-charge gain, a credit the client nets in COGS 'Overhead' and the master shows in G&A Back office support. [Client ref: 'P&L_2026(Mo)'!AY16]
A35: Total cost of sales | B35: 1.4092933e+08 | C35: =IS_Alif!C21 -> 1.3371511e+08 | D35: =C35-B35 -> -7214215.1 | E35: -7,214,215.08 = freight-out reclass to S&D -7,699,912.44 + detention charges kept in COGS +119,718.69 + warehouse rent in COGS +328,772.13 + 700042 credit taken out of COGS +37,206.54. Indirect salaries stay in COGS above gross profit. [Client ref: 'P&L_2026(Mo)'!AY18]
A36: GROSS PROFIT / (LOSS) | B36: -14461403 | C36: =IS_Alif!C23 -> -7247188.2 | D36: =C36-B36 -> 7214215.1 | E36: +7,214,215.08: equal and opposite to the COGS variance. Gross margin is -5.73% in the master vs -11.43% in the client file. The difference comes only from moving costs below gross profit; EBITDA and the net result are unchanged. [Client ref: 'P&L_2026(Mo)'!AY20]
A37: SELLING & DISTRIBUTION (S&D)
A38: Freight-out & shipping (S&D) | B38: 1697274.5 | C38: =IS_Alif!C31 -> 9397187 | D38: =C38-B38 -> 7699912.4 | E38: +7,699,912.44 = 700067 FREIGHT-OUT EXPORT (SAR 6,930,832.17) + 700077 Freight - Drayage (SAR 769,080.27), reclassified from COGS to S&D under IFRS. 700060 Freight-out local (Alif SAR 1,697,274.54 / VH SAR 190,520.00) agrees. [Client ref: 'P&L_2026(Mo)'!AY28]
A39: Advertising, exhibitions, commission & buffet (S&D) | B39: 24731.11 | C39: =IS_Alif!C27+IS_Alif!C28+IS_Alif!C29+IS_Alif!C30 -> 136856.06 | D39: =C39-B39 -> 112124.95 | E39: +112,124.95: the master puts 100% of the buffet/food GLs (700016, 700039) in S&D by nature (Map). The client allocates them by cost centre: SAR 15,674.65 (sales department) in S&D and SAR 112,124.95 in G&A. Advertising (SAR 9,056.46) agrees. [Client ref: 'P&L_2026(Mo)'!AY31+AY32+AY33+AY34]
A40: Sales-department salaries, rent, utilities & admin costs (client departmental carve-out) | B40: 4543999 | C40: 0 | D40: =C40-B40 -> -4543999 | E40: -4,543,999.03: the client takes sales-department costs out of G&A using cost-centre data (Pivot_S&M / GLExpenses_S&M): salaries 3,770,973.11; rent 401,502.63 (700057 warehouse 328,772.13 + 700069 office 72,730.50); utilities 147,939.54; business travel 135,663.35; govt fees 70,101.74; back office 9,669.90; IT 8,148.76. The master is driven by GL account and classifies by nature through the Map. The TB has no cost-centre dimension, so these stay in G&A (700057 in COGS). EBITDA is unaffected. [Client ref: 'P&L_2026(Mo)'!AY23+AY24+AY25+AY26+AY27+AY29+AY30]
A41: Total selling & distribution | B41: 6266004.7 | C41: =IS_Alif!C32 -> 9534043 | D41: =C41-B41 -> 3268038.4 | E41: +3,268,038.37 = freight-out reclass +7,699,912.44 + buffet by nature +112,124.95 - client departmental carve-out -4,543,999.03. [Client ref: 'P&L_2026(Mo)'!AY36]
A42: GENERAL & ADMINISTRATIVE (G&A)
...

Sheet Problem_Areas_&_Solutions
A1: PROBLEM AREAS & SOLUTIONS — MANAGERIAL ANALYSIS (Alif / VH IFRS reporting engine, Sep-2026 close)
A2: Purpose: summarise the data problems, accounting fixes and operational controls found while reconciling the master engine to the client reference file (FS report 202609 IFRS.xlsx). Areas 1-4 are the core rectifications; areas 5-10 are further findings from the side-by-side comparison. Live check values: see Checks sections 2, 3, 6 and 7.
A4: # | B4: Module / Area | C4: Identified Problem / Risk | D4: Technical / Accounting Cause | E4: Implemented Solution | F4: Quantified Impact / Evidence (SAR) | G4: Operational Control & Status
A5: CORE RECTIFICATIONS (required)
A6: 1 | B6: Area 1: Unmapped GL Account Drift (TB copy-paste → Map) | C6: New GL codes created in the ERP during the month (e.g. 520049, 520050, 700080) show "⚠ UNMAPPED" in TB_Input G-J when the monthly TB is pasted. Their balances then fall out of the IS/BS, so the BS does not balance and the P&L is misstated, with nothing obvious to warn the user. | D6: Statement lines are built with SUMIFS on the Map-derived FS Line (TB col I). A GL ID that is missing from Map!A returns the IFERROR fallback "⚠ UNMAPPED", which matches no statement line, so its balance is excluded. The chart of accounts changes faster than the Map is maintained. | E6: Automated Map-sheet extension: the INDEX/MATCH lookups cover Map!A2:A400, so a new ID appended to Map flows through to every statement with no formula changes. Checks tab alert: Checks!B10:D10 counts ⚠ UNMAPPED rows and B11:D11 sums their balances; TB_Input!M2 flags unmapped rows with a balance. The Sep-26 additions are in Map rows 293-295. | F6: 520049 SAR 598.80 + 700080 SAR 130,801.58 (520050 nil net) = SAR 131,400.38 that would have leaked. Now: unmapped rows = 0 (Checks!D10), unmapped balance = 0.00 (Checks!D11). | G6: Monthly: after pasting the TB, Checks section 2 must show 0 / PASS before the statements are reviewed. Owner: GL accountant. Status: CLOSED for Sep-26; control in place.
A7: 2 | B7: Area 2: Sales Revenue Truncation (multi-row 410001) | C7: SALES REVENUE (410001) appears on many rows in the ERP export (multi-line credits, repeated IDs, manual add/remove sales journals). A lookup that returns the first match (VLOOKUP/INDEX-MATCH) under-reports revenue badly. | D7: First-match lookups stop at the first 410001 row. The ERP export does not aggregate by account and manual sales JVs post to the same ID, so a single-row model only captured SAR 5.81m of Alif sales. | E7: Full-column dynamic SUMIFS on raw TB rows: IS Sales = -SUMIFS(TB!F:F, TB!I:I,"Sales", TB!G:G,"IS") + SUMIFS(TB!C:C, …). Every row with the same FS Line is aggregated, whatever the number of rows or duplicate IDs. TB integrity checks (Checks section 1) confirm ΣCB = 0 and CB = OB + Dr − Cr. | F7: Alif 18 × 410001 rows aggregated: sales SAR 126,467,923.88 (was 5,810,727.40; +120,657,196.48). Consolidated SAR 170,911,675.61 = client P&L_2026(Mo)!AX8 (variance 0.00). | G7: Paste ALL numeric rows (including duplicates and manual rows); never de-duplicate the TB. Row-count tie-outs are in TB_Comparison_Justification rows 23-24. Status: CLOSED.
A8: 3 | B8: Area 3: IFRS Freight vs. COGS Placement | C8: Outbound freight (freight-out local, export freight, drayage) was posted to COGS. This understates gross margin and makes GM% hard to compare with peers and budget. | D8: Under IAS 2.10/2.16(d), inventory cost covers only the costs of bringing goods to their present location and condition. Distribution and delivery to customers after the point of sale is a selling cost, so it belongs in S&D below gross profit. The GL range 7000xx mixes selling and production items. | E8: Reclassification to S&D under IFRS: Map lines for 700060, 700067 and 700077 are set to "Selling and Marketing / Freight and shipping expenses (S&D)" on a separate IS line below gross profit. Inbound/production-related freight (700068, 700047 detention) stays in COGS freight. | F8: 700067 SAR 6,930,832.17 + 700077 SAR 769,080.27 moved out of COGS (700060 SAR 1,697,274.54 already S&D). Alif GP: master -7,247,188.21 vs client -14,461,403.28; GM% -5.73% vs -11.43%. EBITDA and net result are unchanged. | G8: Any new freight GL must be tagged inbound (COGS) or outbound (S&D) when it is created. Report GM% on the IFRS basis consistently in management packs. Status: CLOSED.
A9: 4 | B9: Area 4: Factory Indirect Labor in COGS | C9: Factory supervisory and indirect floor labour (supervisors, casual labour, indirect food, factory business trips) could fall outside COGS or be mixed with admin salaries. That would overstate gross margin and understate the absorbed production overhead. | D9: IAS 2.12 requires fixed and variable production overheads, including indirect labour, in the cost of conversion. The 6000xx range was partly mapped to "Overhead - Rent Labor" (600035), and manual JVs move 600002-600045 balances into 600001 "Indirect Salaries", so a mis-mapped account would carry the cost out of the labour line. | E9: Explicit COGS "Overhead - Labor Cost" mapping: 600001, 600035, 600041 and 600044 are set to IS / Cost of sales / Overhead - Labor Cost (Notes: Indirect Salaries); 600035 corrected from "Overhead - Rent Labor". The IS line is relabelled "Overhead - Labor Cost (factory indirect salaries)". Admin salaries 700001 stay in G&A below gross profit. New Checks section 6 locks this in. | F9: Factory indirect salaries in COGS: Alif SAR 5,969,397.02, VH SAR 1,078,114.31, Consolidated SAR 7,047,511.33 (client 6,991,304.70; +56,206.63 = 600044/600043 factory costs the client shows as "Overhead", still in COGS). Admin salaries in G&A: Alif SAR 11,195,522.34. | G9: Checks section 6 rows must PASS every month. Payroll to tag new factory cost centres to the 6000xx range. Status: CLOSED.
A10: ADDITIONAL FINDINGS FROM THE SIDE-BY-SIDE COMPARISON
A11: 5 | B11: Intercompany elimination (consolidation) | C11: The Alif ↔ VH current accounts do not agree, and the client consolidated BS adds the two entities together with no IC elimination. | D11: Alif a/c 270005 due to VH SAR 1,625,866.01 vs VH a/c 330004 due from Alif SAR 1,606,622.15. The difference is likely cut-off or in-transit items. IFRS 10.B86(c) requires intragroup balances to be eliminated in full. | E11: Automatic elimination table on BS_Consol (H53:H54) linked to the TB accounts. The unreconciled SAR 19,243.86 is disclosed as a separate "Consolidation difference" equity line (no P&L plug). IS/CF IC tables are ready for IC trading entries. | F11: Consolidated equity +19,243.86 and Due to RP -19,243.86 vs client. No IC trading found in the Sep-26 TBs. | G11: Month-end IC confirmation between the Alif and VH accountants; clear the difference before the year-end audit. Status: OPEN (reconciliation).
A12: 6 | B12: S&D vs G&A split: by nature vs by department | C12: The client builds S&D from a cost-centre pivot (GLExpenses_S&M). The master classifies by GL nature. As a result S&D/G&A subtotals differ even though EBITDA agrees. | D12: The TB export has no cost-centre dimension, so the master cannot reproduce the departmental carve-out (sales salaries 3.77m, rent 0.40m, utilities 0.15m, etc.). | E12: Differences are fully reconciled and justified line by line in FS_SideBySide_Comparison Section A. EBITDA agrees to SAR 0.00 for Alif. | F12: S&D carve-out SAR 4,543,999.03; buffet by nature SAR 131,192.37. | G12: Decision needed: (a) add a cost-centre column to the TB export, or (b) accept by-nature presentation for IFRS. Status: OPEN (policy decision).
A13: 7 | B13: VH machine depreciation presentation (700052) | C13: VH machine depreciation is in COGS in the client file but below EBITDA in the master. VH gross profit and EBITDA differ by SAR 414,375.81. | D13: The Map treats 7000xx depreciation GLs as period costs. For production machinery, IAS 2.12 requires depreciation in production overhead (COGS), as is already done for Alif 600029. | E13: Not changed in the engine (outside the approved scope). Flagged and justified in the comparison. Recommendation: re-map 700052 to "Depreciation - Machines" once the asset register confirms the machines are used in production. | F13: VH COGS -414,375.81 / EBITDA +414,375.81 vs client; net result unaffected. | G13: Fixed-asset accountant to confirm asset usage; update Map row for 700052. Status: OPEN (recommendation).
A14: 8 | B14: Cash-flow classification differences | C14: Related-party funding, finance cost paid and the RoU derecognition are classified differently, so operating cash flow differs by about SAR 96m (Alif) although the net change in cash agrees. | D14: IAS 7.17: shareholder/group funding is a financing activity. The master's TB-based simplification assumes finance cost paid = charge. The client rolls Murabaha profit into the loan balance. The June-2026 lease modification is non-cash (IAS 7.43). | E14: Master presents RP funding in financing and finance cost paid in operating. All differences are explained line by line in Section C. Net change in cash agrees within SAR 1.63 (client rounding). | F14: RP funding Alif 85.72m / VH 7.49m; finance cost paid 8.88m (Alif); RoU 1.57m. | G14: Recommendation: add a non-cash lease adjustment row and a finance-cost-paid schedule from the Murabaha statements. Status: OPEN (enhancement).
A15: 9 | B15: Opening balances: audited FS vs TB opening | C15: The client CF uses the audited 31-Dec-2025 balance sheet as the opening position. The master uses TB opening balances. Individual working-capital movements therefore differ. | D15: Year-end audit reclassifications (receivables/prepayments gross-up of SAR 6.52m against payables/EOSB) were not booked back into the GL opening balances. | E15: Variances are explained and shown to net to nil (SAR -0.23) across receivables, prepayments, payables and EOSB in Section C. | F15: TR 1,667,351.53; prepayments 4,857,328.47; payables 7,408,647.69; EOSB 883,967.92. | G15: Book the audit reclassifications in the GL opening period (or keep a mapping override) so that TB OB = audited BS. Status: OPEN.
A16: 10 | B16: Balance-sheet equilibrium (VH rounding residual) | C16: VH and the consolidated BS showed a SAR 0.004 difference: the TB carries an unclosed opening P&L rounding balance. | D16: The opening P&L balance (Σ IS-account OB) was not included in retained earnings, so it appeared in neither the result nor equity. | E16: BS_Alif/BS_VH retained earnings now include the unclosed opening P&L per TB (−SUMIFS of IS opening balances). This is the correct accounting home and avoids a plug. The difference is now exactly 0.00 for Alif, VH and Consolidated. | F16: Before: VH 0.004 / Consolidated 0.004. After: 0.00 / 0.00 / 0.00 (Checks row 15). | G16: Checks section 3 must show 0.00. Status: CLOSED.
A18: MANAGEMENT SUMMARY
A19: • | B19: Data challenges: the monthly ERP TB export is a raw, row-level dump (repeated account IDs, manual JVs, new GL codes, no cost-centre dimension). The engine must therefore aggregate with SUMIFS and must never rely on first-match lookups or a static account list.
A20: • | B20: Accounting fixes: IFRS presentation rules are applied by Map: outbound freight in S&D (IAS 2), factory indirect labour in COGS (IAS 2.12), intragroup balances eliminated (IFRS 10), and unclosed opening P&L carried in retained earnings. Every fix is formula-driven and reversible in Map, with no hard-coded adjustments.
A21: • | B21: Operational solutions: one control panel (Checks) with PASS/REVIEW flags for TB integrity, mapping coverage, BS equilibrium, cross-statement ties, COGS classification and the client tie-out; a side-by-side comparison that documents every presentation difference; and a monthly checklist in the README.
A22: • | B22: Result for Sep-26: net result, total assets and closing cash agree to the client file for Alif, VH and Consolidated (within SAR 0.01; cash within client rounding of SAR 0.71). 0 unmapped GL rows. BS difference 0.00 SAR. Open items: #5 IC reconciliation, #6 S&D policy, #7 VH 700052, #8 CF enhancements, #9 opening-balance alignment.

Sheet IS_Consol
A1: ALIF GROUP — CONSOLIDATED (Alif + VH)
A2: Statement of Profit or Loss and Other Comprehensive Income (IFRS)
A3: Nine months ended 30 September 2026 (year-to-date, SAR)
C5: Alif | D5: VH | E5: Eliminations | F5: Consolidated | H5: FS Line (Map key)
A6: Sales | C6: =IS_Alif!C6 -> 1.2646792e+08 | D6: =IS_VH!C6 -> 44443752 | E6: =-SUMIFS($H$69:$H$71,$G$69:$G$71,$H6) -> 0 | F6: =SUM(C6:E6) -> 1.7091168e+08 | H6: Sales
A8: Cost of sales
A9: Raw materials | C9: =IS_Alif!C9 -> 94755694 | D9: =IS_VH!C9 -> 38877735 | E9: =-SUMIFS($H$69:$H$71,$G$69:$G$71,$H9) -> 0 | F9: =SUM(C9:E9) -> 1.3363343e+08 | H9: Raw materials
A10: Direct Labor | C10: =IS_Alif!C10 -> 15043743 | D10: =IS_VH!C10 -> 993325.07 | E10: =-SUMIFS($H$69:$H$71,$G$69:$G$71,$H10) -> 0 | F10: =SUM(C10:E10) -> 16037068 | H10: Direct Labor
A11: Freight expenses | C11: =IS_Alif!C11 -> 173224.89 | D11: =IS_VH!C11 -> 0 | E11: =-SUMIFS($H$69:$H$71,$G$69:$G$71,$H11) -> 0 | F11: =SUM(C11:E11) -> 173224.89 | H11: Freight expenses
A12: Customs duties and clearances | C12: =IS_Alif!C12 -> 2270031.4 | D12: =IS_VH!C12 -> 0 | E12: =-SUMIFS($H$69:$H$71,$G$69:$G$71,$H12) -> 0 | F12: =SUM(C12:E12) -> 2270031.4 | H12: Customs duties and clearances
A13: Depreciation — machinery and equipment | C13: =IS_Alif!C13 -> 6489832.7 | D13: =IS_VH!C13 -> 0 | E13: =-SUMIFS($H$69:$H$71,$G$69:$G$71,$H13) -> 0 | F13: =SUM(C13:E13) -> 6489832.7 | H13: Depreciation - Machines
A14: Overhead - Consumables & SP | C14: =IS_Alif!C14 -> 3112107.3 | D14: =IS_VH!C14 -> 95389.197 | E14: =-SUMIFS($H$69:$H$71,$G$69:$G$71,$H14) -> 0 | F14: =SUM(C14:E14) -> 3207496.5 | H14: Overhead - Consumables & SP
A15: Overhead - Insurance | C15: =IS_Alif!C15 -> 3773.297 | D15: =IS_VH!C15 -> 0 | E15: =-SUMIFS($H$69:$H$71,$G$69:$G$71,$H15) -> 0 | F15: =SUM(C15:E15) -> 3773.297 | H15: Overhead - Insurance
A16: Overhead - Labor Cost (factory indirect salaries) | C16: =IS_Alif!C16 -> 5969397 | D16: =IS_VH!C16 -> 1078114.3 | E16: =-SUMIFS($H$69:$H$71,$G$69:$G$71,$H16) -> 0 | F16: =SUM(C16:E16) -> 7047511.3 | H16: Overhead - Labor Cost
A17: Overhead - R&M | C17: =IS_Alif!C17 -> 3382853.5 | D17: =IS_VH!C17 -> 136041.94 | E17: =-SUMIFS($H$69:$H$71,$G$69:$G$71,$H17) -> 0 | F17: =SUM(C17:E17) -> 3518895.5 | H17: Overhead - R&M
A18: Overhead - Rent | C18: =IS_Alif!C18 -> 358632.93 | D18: =IS_VH!C18 -> 0 | E18: =-SUMIFS($H$69:$H$71,$G$69:$G$71,$H18) -> 0 | F18: =SUM(C18:E18) -> 358632.93 | H18: Overhead - Rent
A19: Overhead - Rent Labor | C19: =IS_Alif!C19 -> 0 | D19: =IS_VH!C19 -> 0 | E19: =-SUMIFS($H$69:$H$71,$G$69:$G$71,$H19) -> 0 | F19: =SUM(C19:E19) -> 0 | H19: Overhead - Rent Labor
A20: Overhead - Utility | C20: =IS_Alif!C20 -> 2155822.3 | D20: =IS_VH!C20 -> 769810.52 | E20: =-SUMIFS($H$69:$H$71,$G$69:$G$71,$H20) -> 0 | F20: =SUM(C20:E20) -> 2925632.9 | H20: Overhead - Utility
A21: Total cost of sales | C21: =SUM(C9:C20) -> 1.3371511e+08 | D21: =SUM(D9:D20) -> 41950416 | E21: =SUM(E9:E20) -> 0 | F21: =SUM(F9:F20) -> 1.7566553e+08
A23: GROSS PROFIT /(LOSS) | C23: =C6-C21 -> -7247188.2 | D23: =D6-D21 -> 2493336.1 | E23: =E6-E21 -> 0 | F23: =F6-F21 -> -4753852.1
A24: Gross margin % | F24: =F23/F6 -> -0.027814672
A26: Selling and distribution expenses
A27: Advertising and promotion expenses | C27: =IS_Alif!C27 -> 9056.458 | D27: =IS_VH!C27 -> 0 | E27: =-SUMIFS($H$69:$H$71,$G$69:$G$71,$H27) -> 0 | F27: =SUM(C27:E27) -> 9056.458 | H27: Advertising and promotion expenses
A28: Buffet expenses | C28: =IS_Alif!C28 -> 127799.6 | D28: =IS_VH!C28 -> 19067.418 | E28: =-SUMIFS($H$69:$H$71,$G$69:$G$71,$H28) -> 0 | F28: =SUM(C28:E28) -> 146867.02 | H28: Buffet expenses
A29: Commission expenses | C29: =IS_Alif!C29 -> 0 | D29: =IS_VH!C29 -> 0 | E29: =-SUMIFS($H$69:$H$71,$G$69:$G$71,$H29) -> 0 | F29: =SUM(C29:E29) -> 0 | H29: Commission expenses
A30: Exhibitions | C30: =IS_Alif!C30 -> 0 | D30: =IS_VH!C30 -> 0 | E30: =-SUMIFS($H$69:$H$71,$G$69:$G$71,$H30) -> 0 | F30: =SUM(C30:E30) -> 0 | H30: Exhibitions
A31: Freight and shipping expenses | C31: =IS_Alif!C31 -> 9397187 | D31: =IS_VH!C31 -> 190520 | E31: =-SUMIFS($H$69:$H$71,$G$69:$G$71,$H31) -> 0 | F31: =SUM(C31:E31) -> 9587707 | H31: Freight and shipping expenses (S&D)
A32: Total selling and distribution | C32: =SUM(C27:C31) -> 9534043 | D32: =SUM(D27:D31) -> 209587.42 | E32: =SUM(E27:E31) -> 0 | F32: =SUM(F27:F31) -> 9743630.5
A34: General and administrative expenses
A35: Salaries and wages (administrative, incl. 700001) | C35: =IS_Alif!C35 -> 11195522 | D35: =IS_VH!C35 -> 1546060.7 | E35: =-SUMIFS($H$69:$H$71,$G$69:$G$71,$H35) -> 0 | F35: =SUM(C35:E35) -> 12741583 | H35: Salaries and wages
A36: Utilities | C36: =IS_Alif!C36 -> 772352.67 | D36: =IS_VH!C36 -> 52133.249 | E36: =-SUMIFS($H$69:$H$71,$G$69:$G$71,$H36) -> 0 | F36: =SUM(C36:E36) -> 824485.92 | H36: Utilities
A37: Business travel | C37: =IS_Alif!C37 -> 253285.36 | D37: =IS_VH!C37 -> 30392.763 | E37: =-SUMIFS($H$69:$H$71,$G$69:$G$71,$H37) -> 0 | F37: =SUM(C37:E37) -> 283678.12 | H37: Business travel
A38: Training | C38: =IS_Alif!C38 -> 0 | D38: =IS_VH!C38 -> 0 | E38: =-SUMIFS($H$69:$H$71,$G$69:$G$71,$H38) -> 0 | F38: =SUM(C38:E38) -> 0 | H38: Training
A39: IT expenses | C39: =IS_Alif!C39 -> 536718.32 | D39: =IS_VH!C39 -> 1227.822 | E39: =-SUMIFS($H$69:$H$71,$G$69:$G$71,$H39) -> 0 | F39: =SUM(C39:E39) -> 537946.14 | H39: IT expenses
A40: Govt license and fees (including modon) | C40: =IS_Alif!C40 -> 369690.55 | D40: =IS_VH!C40 -> 54118.036 | E40: =-SUMIFS($H$69:$H$71,$G$69:$G$71,$H40) -> 0 | F40: =SUM(C40:E40) -> 423808.59 | H40: Govt license and fees (including modon)
A41: Rent | C41: =IS_Alif!C41 -> 75052.053 | D41: =IS_VH!C41 -> 0 | E41: =-SUMIFS($H$69:$H$71,$G$69:$G$71,$H41) -> 0 | F41: =SUM(C41:E41) -> 75052.053 | H41: Rent
A42: Back office support | C42: =IS_Alif!C42 -> 114815.34 | D42: =IS_VH!C42 -> 12049.9 | E42: =-SUMIFS($H$69:$H$71,$G$69:$G$71,$H42) -> 0 | F42: =SUM(C42:E42) -> 126865.24 | H42: Back office Support
A43: AIMS expenses | C43: =IS_Alif!C43 -> 0 | D43: =IS_VH!C43 -> 0 | E43: =-SUMIFS($H$69:$H$71,$G$69:$G$71,$H43) -> 0 | F43: =SUM(C43:E43) -> 0 | H43: AIMS expenses
A44: Total general and administrative | C44: =SUM(C35:C43) -> 13317437 | D44: =SUM(D35:D43) -> 1695982.5 | E44: =SUM(E35:E43) -> 0 | F44: =SUM(F35:F43) -> 15013419
A46: Impairment losses on trade receivables (bad debts) | C46: =IS_Alif!C46 -> 0 | D46: =IS_VH!C46 -> 0 | E46: =-SUMIFS($H$69:$H$71,$G$69:$G$71,$H46) -> 0 | F46: =SUM(C46:E46) -> 0 | H46: Bad debts expense
...

Sheet BS_Consol
A1: ALIF GROUP — CONSOLIDATED (Alif + VH)
A2: Statement of Financial Position (IFRS)
A3: As at 30 September 2026 (SAR)
C5: Alif | D5: VH | E5: Eliminations | F5: Consolidated | H5: FS Line (Map key)
A7: ASSETS
A8: Non-current assets
A9: Property, plant and equipment | C9: =BS_Alif!C9 -> 1.5638441e+08 | D9: =BS_VH!C9 -> 27374670 | E9: =-SUMIFS($H$53:$H$55,$G$53:$G$55,$H9) -> 0 | F9: =SUM(C9:E9) -> 1.8375908e+08 | H9: Property, plant and equipment
A10: Right-of-use assets | C10: =BS_Alif!C10 -> 978082.35 | D10: =BS_VH!C10 -> 145144.78 | E10: =-SUMIFS($H$53:$H$55,$G$53:$G$55,$H10) -> 0 | F10: =SUM(C10:E10) -> 1123227.1 | H10: Right of use
A11: Due from related parties | C11: =BS_Alif!C11 -> 0 | D11: =BS_VH!C11 -> 104625.32 | E11: =-SUMIFS($H$53:$H$55,$G$53:$G$55,$H11) -> 0 | F11: =SUM(C11:E11) -> 104625.32 | H11: Due from RP
A12: Total non-current assets | C12: =SUM(C9:C11) -> 1.573625e+08 | D12: =SUM(D9:D11) -> 27624440 | E12: =SUM(E9:E11) -> 0 | F12: =SUM(F9:F11) -> 1.8498694e+08
A14: Current assets
A15: Inventories | C15: =BS_Alif!C15 -> 68750141 | D15: =BS_VH!C15 -> 32176575 | E15: =-SUMIFS($H$53:$H$55,$G$53:$G$55,$H15) -> 0 | F15: =SUM(C15:E15) -> 1.0092672e+08 | H15: Inventories
A16: Trade receivables | C16: =BS_Alif!C16 -> 21529785 | D16: =BS_VH!C16 -> 6772222.1 | E16: =-SUMIFS($H$53:$H$55,$G$53:$G$55,$H16) -> 0 | F16: =SUM(C16:E16) -> 28302007 | H16: Trade receivables
A17: Prepaid expenses | C17: =BS_Alif!C17 -> 10246501 | D17: =BS_VH!C17 -> 711151.25 | E17: =-SUMIFS($H$53:$H$55,$G$53:$G$55,$H17) -> 0 | F17: =SUM(C17:E17) -> 10957652 | H17: Prepaid expenses
A18: Cash and cash equivalents | C18: =BS_Alif!C18 -> 30034455 | D18: =BS_VH!C18 -> 2763170.1 | E18: =-SUMIFS($H$53:$H$55,$G$53:$G$55,$H18) -> 0 | F18: =SUM(C18:E18) -> 32797626 | H18: Cash and cash equivalents
A19: Total current assets | C19: =SUM(C15:C18) -> 1.3056088e+08 | D19: =SUM(D15:D18) -> 42423118 | E19: =SUM(E15:E18) -> 0 | F19: =SUM(F15:F18) -> 1.72984e+08
A21: TOTAL ASSETS | C21: =C12+C19 -> 2.8792338e+08 | D21: =D12+D19 -> 70047559 | E21: =E12+E19 -> 0 | F21: =F12+F19 -> 3.5797094e+08
A23: EQUITY AND LIABILITIES
A24: Equity
A25: Share capital | C25: =BS_Alif!C25 -> 35335000 | D25: =BS_VH!C25 -> 500000 | E25: =-SUMIFS($H$53:$H$55,$G$53:$G$55,$H25) -> 0 | F25: =SUM(C25:E25) -> 35835000 | H25: Share capital
A26: Additional contribution from shareholders | C26: =BS_Alif!C26 -> 1.2225532e+08 | D26: =BS_VH!C26 -> 22500000 | E26: =-SUMIFS($H$53:$H$55,$G$53:$G$55,$H26) -> 0 | F26: =SUM(C26:E26) -> 1.4475532e+08 | H26: Additional contribution from shareholders
A27: Statutory reserve | C27: =BS_Alif!C27 -> 7846137 | D27: =BS_VH!C27 -> 0 | E27: =-SUMIFS($H$53:$H$55,$G$53:$G$55,$H27) -> 0 | F27: =SUM(C27:E27) -> 7846137 | H27: Statutory reserve
A28: Retained earnings | C28: =BS_Alif!C28 -> -1.0726718e+08 | D28: =BS_VH!C28 -> -16258799 | E28: =-SUMIFS($H$53:$H$55,$G$53:$G$55,$H28) -> 0 | F28: =SUM(C28:E28) -> -1.2352598e+08 | H28: Retained earnings
A29: Result for the period (per statement of profit or loss) | C29: =IS_Alif!C65 -> -40498413 | D29: =IS_VH!C65 -> -1356565.7 | E29: =IS_Consol!E65 -> 0 | F29: =SUM(C29:E29) -> -41854979
A30: Consolidation difference on intercompany balances | E30: =SUMIFS($H$53:$H$55,$I$53:$I$55,"L")+SUMIFS($H$53:$H$55,$I$53:$I$55,"E")-SUMIFS($H$53:$H$55,$I$53:$I$55,"A") -> 19243.861 | F30: =E30 -> 19243.861 | J30: (automatic: unreconciled IC balance difference, see elimination table & README)
A31: Total equity | C31: =SUM(C25:C30) -> 17670860 | D31: =SUM(D25:D30) -> 5384635.6 | E31: =SUM(E25:E30) -> 19243.861 | F31: =SUM(F25:F30) -> 23074740
A33: Non-current liabilities
A34: Due to related parties | C34: =BS_Alif!C33 -> 1.0102855e+08 | D34: =BS_VH!C33 -> 40404058 | E34: =-SUMIFS($H$53:$H$55,$G$53:$G$55,$H34) -> -19243.861 | F34: =SUM(C34:E34) -> 1.4141337e+08 | H34: Due to related parties
A35: End-of-service indemnities | C35: =BS_Alif!C34 -> 4045881 | D35: =BS_VH!C34 -> 812062.07 | E35: =-SUMIFS($H$53:$H$55,$G$53:$G$55,$H35) -> 0 | F35: =SUM(C35:E35) -> 4857943.1 | H35: End-of-service indemnities
A36: Lease liabilities non-current | C36: =BS_Alif!C35 -> 1165712.7 | D36: =BS_VH!C35 -> 142956.96 | E36: =-SUMIFS($H$53:$H$55,$G$53:$G$55,$H36) -> 0 | F36: =SUM(C36:E36) -> 1308669.7 | H36: Lease liabilities non-current
A37: Provision for evacuation | C37: =BS_Alif!C36 -> 4931250.8 | D37: =BS_VH!C36 -> 276000 | E37: =-SUMIFS($H$53:$H$55,$G$53:$G$55,$H37) -> 0 | F37: =SUM(C37:E37) -> 5207250.8 | H37: Provision for evacuation
A38: Total non-current liabilities | C38: =SUM(C34:C37) -> 1.111714e+08 | D38: =SUM(D34:D37) -> 41635077 | E38: =SUM(E34:E37) -> -19243.861 | F38: =SUM(F34:F37) -> 1.5278723e+08
A40: Current liabilities
A41: Short-term Murabaha loans | C41: =BS_Alif!C40 -> 1.368453e+08 | D41: =BS_VH!C40 -> 19773450 | E41: =-SUMIFS($H$53:$H$55,$G$53:$G$55,$H41) -> 0 | F41: =SUM(C41:E41) -> 1.5661875e+08 | H41: Short-term Murabaha loans
A42: Trade payables, accruals and other credit balances | C42: =BS_Alif!C41 -> 22235818 | D42: =BS_VH!C41 -> 3254395.2 | E42: =-SUMIFS($H$53:$H$55,$G$53:$G$55,$H42) -> 0 | F42: =SUM(C42:E42) -> 25490214 | H42: Tade payables and Accuals & other credit balances
A43: Zakat provision | C43: =BS_Alif!C42 -> 0 | D43: =BS_VH!C42 -> 0 | E43: =-SUMIFS($H$53:$H$55,$G$53:$G$55,$H43) -> 0 | F43: =SUM(C43:E43) -> 0 | H43: Zakat provision
A44: Total current liabilities | C44: =SUM(C41:C43) -> 1.5908112e+08 | D44: =SUM(D41:D43) -> 23027846 | E44: =SUM(E41:E43) -> 0 | F44: =SUM(F41:F43) -> 1.8210897e+08
A46: TOTAL LIABILITIES | C46: =C38+C44 -> 2.7025252e+08 | D46: =D38+D44 -> 64662923 | E46: =E38+E44 -> -19243.861 | F46: =F38+F44 -> 3.348962e+08
A48: TOTAL EQUITY AND LIABILITIES | C48: =C31+C46 -> 2.8792338e+08 | D48: =D31+D46 -> 70047559 | E48: =E31+E46 -> 0 | F48: =F31+F46 -> 3.5797094e+08
A49: Balance check: TOTAL ASSETS − TOTAL EQUITY AND LIABILITIES | C49: =C21-C48 -> 0 | D49: =D21-D48 -> 0 | E49: =E21-E48 -> 0 | F49: =F21-F48 -> 0 | G49: Balance-sheet difference must be nil (±0.01 SAR); the refreshed YTD TB is not plugged.
...

Sheet CF_Consol
A1: ALIF GROUP — CONSOLIDATED (Alif + VH)
A2: Statement of Cash Flows (indirect method)
A3: Nine months ended 30 September 2026 (SAR)
C5: Alif | D5: VH | E5: Eliminations | F5: Consolidated | H5: FS Line (Map key)
A7: OPERATING ACTIVITIES
A8: Profit /(loss) before zakat | C8: =IS_Alif!C57 -> -40498413 | D8: =IS_VH!C57 -> -1356565.7 | E8: =-SUMIFS($H$48:$H$50,$G$48:$G$50,$A8) -> 0 | F8: =SUM(C8:E8) -> -41854979
A9: Adjustments for non-cash items:
A10: Depreciation and amortisation | C10: =IS_Alif!C52+IS_Alif!C13 -> 8375830.8 | D10: =IS_VH!C52+IS_VH!C13 -> 1082789.8 | E10: =-SUMIFS($H$48:$H$50,$G$48:$G$50,$A10) -> 0 | F10: =SUM(C10:E10) -> 9458620.6
A11: Amortisation of pre-operating expenses | C11: =IS_Alif!C53 -> 0 | D11: =IS_VH!C53 -> 0 | E11: =-SUMIFS($H$48:$H$50,$G$48:$G$50,$A11) -> 0 | F11: =SUM(C11:E11) -> 0
A12: Finance costs | C12: =IS_Alif!C54 -> 8880147 | D12: =IS_VH!C54 -> 863818.04 | E12: =-SUMIFS($H$48:$H$50,$G$48:$G$50,$A12) -> 0 | F12: =SUM(C12:E12) -> 9743965
A13: End-of-service indemnities — net movement | C13: =-(SUMIFS(TB_Input_Alif!$F:$F,TB_Input_Alif!$I:$I,$H13,TB_Input_Alif!$G:$G,"BS")-SUMIFS(TB_Input_Alif!$C:$C,TB_Input_Alif!$I:$I,$H13,TB_Input_Alif!$G:$G,"BS")) -> 155441.07 | D13: =-(SUMIFS(TB_Input_VH!$F:$F,TB_Input_VH!$I:$I,$H13,TB_Input_VH!$G:$G,"BS")-SUMIFS(TB_Input_VH!$C:$C,TB_Input_VH!$I:$I,$H13,TB_Input_VH!$G:$G,"BS")) -> 112925.07 | E13: 0 | F13: =SUM(C13:E13) -> 268366.14 | H13: End-of-service indemnities
A14: Provision for evacuation — net movement | C14: =-(SUMIFS(TB_Input_Alif!$F:$F,TB_Input_Alif!$I:$I,$H14,TB_Input_Alif!$G:$G,"BS")-SUMIFS(TB_Input_Alif!$C:$C,TB_Input_Alif!$I:$I,$H14,TB_Input_Alif!$G:$G,"BS")) -> 69077.9 | D14: =-(SUMIFS(TB_Input_VH!$F:$F,TB_Input_VH!$I:$I,$H14,TB_Input_VH!$G:$G,"BS")-SUMIFS(TB_Input_VH!$C:$C,TB_Input_VH!$I:$I,$H14,TB_Input_VH!$G:$G,"BS")) -> 0 | E14: 0 | F14: =SUM(C14:E14) -> 69077.9 | H14: Provision for evacuation
A15: Changes in working capital:
A16: Inventories | C16: =-(SUMIFS(TB_Input_Alif!$F:$F,TB_Input_Alif!$I:$I,$H16,TB_Input_Alif!$G:$G,"BS")-SUMIFS(TB_Input_Alif!$C:$C,TB_Input_Alif!$I:$I,$H16,TB_Input_Alif!$G:$G,"BS")) -> 37367450 | D16: =-(SUMIFS(TB_Input_VH!$F:$F,TB_Input_VH!$I:$I,$H16,TB_Input_VH!$G:$G,"BS")-SUMIFS(TB_Input_VH!$C:$C,TB_Input_VH!$I:$I,$H16,TB_Input_VH!$G:$G,"BS")) -> -24274129 | E16: =-SUMIFS($H$48:$H$50,$G$48:$G$50,$A16) -> 0 | F16: =SUM(C16:E16) -> 13093321 | H16: Inventories
A17: Trade receivables | C17: =-(SUMIFS(TB_Input_Alif!$F:$F,TB_Input_Alif!$I:$I,$H17,TB_Input_Alif!$G:$G,"BS")-SUMIFS(TB_Input_Alif!$C:$C,TB_Input_Alif!$I:$I,$H17,TB_Input_Alif!$G:$G,"BS")) -> -2318054.1 | D17: =-(SUMIFS(TB_Input_VH!$F:$F,TB_Input_VH!$I:$I,$H17,TB_Input_VH!$G:$G,"BS")-SUMIFS(TB_Input_VH!$C:$C,TB_Input_VH!$I:$I,$H17,TB_Input_VH!$G:$G,"BS")) -> -5338748.6 | E17: =-SUMIFS($H$48:$H$50,$G$48:$G$50,$A17) -> 0 | F17: =SUM(C17:E17) -> -7656802.6 | H17: Trade receivables
A18: Prepaid expenses | C18: =-(SUMIFS(TB_Input_Alif!$F:$F,TB_Input_Alif!$I:$I,$H18,TB_Input_Alif!$G:$G,"BS")-SUMIFS(TB_Input_Alif!$C:$C,TB_Input_Alif!$I:$I,$H18,TB_Input_Alif!$G:$G,"BS")) -> -4497030.4 | D18: =-(SUMIFS(TB_Input_VH!$F:$F,TB_Input_VH!$I:$I,$H18,TB_Input_VH!$G:$G,"BS")-SUMIFS(TB_Input_VH!$C:$C,TB_Input_VH!$I:$I,$H18,TB_Input_VH!$G:$G,"BS")) -> -621540.52 | E18: =-SUMIFS($H$48:$H$50,$G$48:$G$50,$A18) -> 0 | F18: =SUM(C18:E18) -> -5118570.9 | H18: Prepaid expenses
